Workbook

Sheet BB-2024-Friday
A1: BB Pg | C1: Suggested | E1: Adj to Rally dist | F1: Dist. To adjust | G1: Dist as per BB | H1: Rally dist | I1: Current Survey | J1: Error | K1: δ | L1: Clue | M1: Speed Limit | N1: Normal-ised Dist | O1: Previous Surveys | U1: Lat. | V1: Long. | W1: Current Survey | Y1: Previous #1 | AA1: Previous #2 | AC1: Previous #3 | CL1: Speed Limit
B2: Terrain | C2: Typ | D2: Asp | O2: #1 Adj'm | P2: #1 Adj | Q2: #2 Adj'm | R2: #2 Adj | S2: #3 Adj'm | T2: #3 Adj | W2: Latitude | X2: Longetude | Y2: Latitude | Z2: Longetude | AA2: Latitude | AB2: Longetude | AC2: Latitude | AD2: Longetude | AE2: BB Pg | AF2: Terrain | AG2: Sugg. Typ | AH2: Sugg. Asp | AI2: Rally dist | AJ2: Typ | AK2: Instr. Num. | AL2: Check Dist | AM2: A Sp | AN2: B Sp | AO2: C Sp | AP2: D Sp | AQ2: Speed Limit | AR2: Clue | AS2: Lat | AT2: Long | AU2: First | AV2: Last | AW2: Lat Long
A3: 22/10/14 | L3: Hillcrest Corner Old Main Road - PMB via Thornville - Howick - Mooiriver - Escort - Colenso - eZakheni - Glencoe - Dannhauser - Hattingspruit - Newcastle | AE3: BB Pg | AF3: Terrain | AG3: Sugg. Typ | AH3: Sugg. Asp | AI3: Rally dist | AJ3: Typ | AK3: Instr. Num. | AL3: Check Dist | AM3: A Sp | AN3: B Sp | AO3: C Sp | AP3: D Sp | AQ3: Speed Limit | AR3: Clue | AS3: Lat | AT3: Long | AU3: First | AV3: Last | AW3: Lat Long | AX3: Lat | AY3: Long | AZ3: IntOdo | BA3: InitFirstA | BB3: IntLastA | BC3: IntFirstB | BD3: IntLastB | BE3: IntFirstC | BF3: IntLastC | BG3: IntFirstD | BH3: IntLastD | BI3: IncDist | BJ3: D.HrA | BK3: D.HrB | BL3: D.HrC | BM3: D.HrD | BN3: HrA | BO3: MinA | BP3: SecA | BQ3: HrB | BR3: MinB | BS3: SecB | BT3: HrC | BU3: MinC | BV3: SecC | BW3: HrD | BX3: MinD | BY3: SecD | BZ3: First A | CA3: Last A | CB3: First B | CC3: Last B | CD3: First C | CE3: Last C | CF3: First D | CG3: Last D | CH3: Time Add A | CI3: Time Add B | CJ3: Time Add C | CK3: Time Add D
A4: 26 | C4: o | D4: 30 | G4: 0 | H4: =ROUND(IF(G4="",N4,IF(P4="",I4,IF(R4="",(I4+(P4+O4))/2,IF(T4="",(I4+(P4+O4)+(R4+Q4))/3,(I4+(P4+O4)+(R4+Q4)+(T4+S4))/4)))),2) -> 0 | I4: 0 | J4: =IF(N4="","",IF((I4-$I$4)=0,0,((I4-$I$4-(N4-$N$4))/(I4-$I$4)))) -> 0 | K4: =(I4-$I$5)-(N4-$N$5) -> 0 | L4: START in left exit lane of P1 parking basement. START of OPEN SECTION. | M4: 60 | N4: =IF(P4="",((I4-I3)+H3),IF(R4="",(P4+O4),IF(T4="",((P4+O4)+(R4+Q4))/2,((P4+O4)+(R4+Q4)+(T4+S4))/3))) -> 0 | P4: 0 | R4: 0 | T4: 0 | U4: =IF(W4="","",IF(Y4="",W4,IF(AA4<1,ROUND((Y4+W4)/2,5),IF(AC4<1,ROUND((Y4+AA4+W4)/3,5),ROUND((Y4+AA4+AC4+W4)/4,5))))) | V4: =IF(X4="","",IF(Z4<1,ROUND(X4,5),IF(AB4<1,ROUND((X4+Z4)/2,5),IF(AD4<1,ROUND((X4+Z4+AB4)/3,5),ROUND((X4+Z4+AB4+AD4)/4,5))))) | AE4: =IF(A4="","",A4) -> 26 | AF4: =IF(B4="","",B4) | AG4: =IF(C4="","",C4) -> o | AH4: =IF(D4="","",D4) -> 30 | AI4: =H4 -> 0 | AJ4: o | AM4: =IF(OR(AJ4="",AJ4="m"),AM3,IF(AH4<>"",AH4,"")) -> 30 | AN4: =IF(AJ4<>"",IF(AJ4="o",VLOOKUP(AM4,OpenSect!$A$1:$D$11,2),IF(AJ4="u",VLOOKUP(AM4,UpHill!$A$1:$D$35,2),IF(AJ4="d",VLOOKUP(AM4,DownHill!$A$3:$D$29,2),IF(AJ4="f",VLOOKUP(AM4,FlatUnd!$A$2:$D$30,2),IF(AJ4="t",VLOOKUP(AM4,TimeAdd!$A$1:$D$176,2),IF(AJ4="l",VLOOKUP(AM4,SLimit!$A$1:$D$8,2),AN3)))))),AN3) -> 30 | AO4: =IF(AJ4<>"",IF(AJ4="o",VLOOKUP(AM4,OpenSect!$A$1:$D$11,3),IF(AJ4="u",VLOOKUP(AM4,UpHill!$A$1:$D$35,3),IF(AJ4="d",VLOOKUP(AM4,DownHill!$A$3:$D$29,3),IF(AJ4="f",VLOOKUP(AM4,FlatUnd!$A$2:$D$30,3),IF(AJ4="t",VLOOKUP(AM4,TimeAdd!$A$1:$D$18,3),IF(AJ4="l",VLOOKUP(AM4,SLimit!$A$1:$D$8,3),AO3)))))),AO3) -> 30 | AP4: =IF(AJ4<>"",IF(AJ4="o",VLOOKUP(AM4,OpenSect!$A$1:$D$11,4),IF(AJ4="u",VLOOKUP(AM4,UpHill!$A$1:$D$35,4),IF(AJ4="d",VLOOKUP(AM4,DownHill!$A$3:$D$29,4),IF(AJ4="f",VLOOKUP(AM4,FlatUnd!$A$2:$D$30,4),IF(AJ4="t",VLOOKUP(AM4,TimeAdd!$A$1:$D$18,4),IF(AJ4="l",VLOOKUP(AM4,SLimit!$A$1:$D$8,4),AP3)))))),AP3) -> 30 | AQ4: =M4 -> 60 | AR4: =L4 -> START in left exit lane of P1 parking basement. START of OPEN SECTION. | AU4: =IF(GroupStTimes!$A$8=0,MIN(CB4,CD4,CF4),MIN(BZ4,CB4,CD4,CF4)) -> 0.25069444 | AV4: =IF(GroupStTimes!$A$8=0,MAX(CC4,CE4,CG4),MAX(CA4,CC4,CE4,CG4)) -> 0.31388889 | AW4: =IF(U4="","",CONCATENATE(FIXED(U4,5)," ",FIXED(V4,5))) | AX4: =IF(AJ4="m",ROUND(W4,5),"") | AY4: =IF(AJ4="m",ROUND(X4,5),"") | AZ4: =AI4 -> 0 | BA4: =TIME(GroupStTimes!A4,GroupStTimes!B4,0) -> 0.25069444 | BB4: =TIME(HOUR(BA4),MINUTE(BA4)+GroupStTimes!A8-1,0) -> 0.25625 | BC4: =TIME(HOUR(BB4),MINUTE(BB4)+1,0) -> 0.25694444 | BD4: =TIME(HOUR(BC4),MINUTE(BC4)+GroupStTimes!B8-1,0) -> 0.30277778 | BE4: =TIME(HOUR(BD4),MINUTE(BD4)+1,0) -> 0.30347222 | BF4: =TIME(HOUR(BE4),MINUTE(BE4)+GroupStTimes!C8-1,0) -> 0.31388889 | BG4: =TIME(HOUR(BF4),MINUTE(BF4)+1,0) -> 0.31458333 | BH4: =TIME(HOUR(BG4),MINUTE(BG4)+GroupStTimes!D8-1,0) -> 0.31388889 | BI4: 0 | BZ4: =BA4 -> 0.25069444 | CA4: =BB4 -> 0.25625 | CB4: =BC4 -> 0.25694444 | CC4: =BD4 -> 0.30277778 | CD4: =BE4 -> 0.30347222 | CE4: =BF4 -> 0.31388889 | CF4: =BG4 -> 0.31458333 | CG4: =BH4 -> 0.31388889 | CL4: 60
A5: 26 | C5: o | D5: 30 | G5: 0.02 | H5: =ROUND(IF(G5="",N5,IF(P5="",I5,IF(R5="",(I5+(P5+O5))/2,IF(T5="",(I5+(P5+O5)+(R5+Q5))/3,(I5+(P5+O5)+(R5+Q5)+(T5+S5))/4)))),2) -> 0.02 | I5: 0.02 | J5: =IF(N5="","",IF((I5-$I$4)=0,0,((I5-$I$4-(N5-$N$4))/(I5-$I$4)))) -> 0 | K5: =(I5-$I$5)-(N5-$N$5) -> 0 | L5: Traffic Light. Turn LEFT into old Main Road | M5: 60 | N5: =IF(P5="",((I5-I4)+H4),IF(R5="",(P5+O5),IF(T5="",((P5+O5)+(R5+Q5))/2,((P5+O5)+(R5+Q5)+(T5+S5))/3))) -> 0.02 | P5: 0.02 | R5: 0.02 | T5: 0.02 | U5: =IF(W5="","",IF(Y5="",W5,IF(AA5<1,ROUND((Y5+W5)/2,5),IF(AC5<1,ROUND((Y5+AA5+W5)/3,5),ROUND((Y5+AA5+AC5+W5)/4,5))))) | V5: =IF(X5="","",IF(Z5<1,ROUND(X5,5),IF(AB5<1,ROUND((X5+Z5)/2,5),IF(AD5<1,ROUND((X5+Z5+AB5)/3,5),ROUND((X5+Z5+AB5+AD5)/4,5))))) | AE5: =IF(A5="","",A5) -> 26 | AF5: =IF(B5="","",B5) | AG5: =IF(C5="","",C5) -> o | AH5: =IF(D5="","",D5) -> 30 | AI5: =H5 -> 0.02 | AJ5: o | AM5: =IF(OR(AJ5="",AJ5="m"),AM4,IF(AH5<>"",AH5,"")) -> 30 | AN5: =IF(AJ5<>"",IF(AJ5="o",VLOOKUP(AM5,OpenSect!$A$1:$D$11,2),IF(AJ5="u",VLOOKUP(AM5,UpHill!$A$1:$D$35,2),IF(AJ5="d",VLOOKUP(AM5,DownHill!$A$3:$D$29,2),IF(AJ5="f",VLOOKUP(AM5,FlatUnd!$A$2:$D$30,2),IF(AJ5="t",VLOOKUP(AM5,TimeAdd!$A$1:$D$176,2),IF(AJ5="l",VLOOKUP(AM5,SLimit!$A$1:$D$8,2),AN4)))))),AN4) -> 30 | AO5: =IF(AJ5<>"",IF(AJ5="o",VLOOKUP(AM5,OpenSect!$A$1:$D$11,3),IF(AJ5="u",VLOOKUP(AM5,UpHill!$A$1:$D$35,3),IF(AJ5="d",VLOOKUP(AM5,DownHill!$A$3:$D$29,3),IF(AJ5="f",VLOOKUP(AM5,FlatUnd!$A$2:$D$30,3),IF(AJ5="t",VLOOKUP(AM5,TimeAdd!$A$1:$D$18,3),IF(AJ5="l",VLOOKUP(AM5,SLimit!$A$1:$D$8,3),AO4)))))),AO4) -> 30 | AP5: =IF(AJ5<>"",IF(AJ5="o",VLOOKUP(AM5,OpenSect!$A$1:$D$11,4),IF(AJ5="u",VLOOKUP(AM5,UpHill!$A$1:$D$35,4),IF(AJ5="d",VLOOKUP(AM5,DownHill!$A$3:$D$29,4),IF(AJ5="f",VLOOKUP(AM5,FlatUnd!$A$2:$D$30,4),IF(AJ5="t",VLOOKUP(AM5,TimeAdd!$A$1:$D$18,4),IF(AJ5="l",VLOOKUP(AM5,SLimit!$A$1:$D$8,4),AP4)))))),AP4) -> 30 | AQ5: =M5 -> 60 | AR5: =L5 -> Traffic Light. Turn LEFT into old Main Road | AU5: =IF(GroupStTimes!$A$8=0,MIN(CB5,CD5,CF5),MIN(BZ5,CB5,CD5,CF5)) -> 0.25071759 | AV5: =IF(GroupStTimes!$A$8=0,MAX(CC5,CE5,CG5),MAX(CA5,CC5,CE5,CG5)) -> 0.31391204 | AW5: =IF(U5="","",CONCATENATE(FIXED(U5,5)," ",FIXED(V5,5))) | AX5: =IF(AJ5="m",ROUND(W5,5),"") | AY5: =IF(AJ5="m",ROUND(X5,5),"") | AZ5: =IF(AND(AM4=AM3,AN4=AN3,AO4=AO3,AP4=AP3,AJ5<>"t"),AZ4,IF(AJ5="t",AI5,AI4)) -> 0 | BA5: =IF(AND($AM4=$AM3,$AN4=AN3,$AO4=$AO3,$AP4=$AP3,$AJ5<>"t"),BA4,BZ4) -> 0.25069444 | BB5: =IF(AND($AM4=$AM3,$AN4=AN3,$AO4=$AO3,$AP4=$AP3,$AJ5<>"t"),BB4,CA4) -> 0.25625 | BC5: =IF(AND($AM4=$AM3,$AN4=AN3,$AO4=$AO3,$AP4=$AP3,$AJ5<>"t"),BC4,CB4) -> 0.25694444 | BD5: =IF(AND($AM4=$AM3,$AN4=AN3,$AO4=$AO3,$AP4=$AP3,$AJ5<>"t"),BD4,CC4) -> 0.30277778 | BE5: =IF(AND($AM4=$AM3,$AN4=AN3,$AO4=$AO3,$AP4=$AP3,$AJ5<>"t"),BE4,CD4) -> 0.30347222 | BF5: =IF(AND($AM4=$AM3,$AN4=AN3,$AO4=$AO3,$AP4=$AP3,$AJ5<>"t"),BF4,CE4) -> 0.31388889 | BG5: =IF(AND($AM4=$AM3,$AN4=AN3,$AO4=$AO3,$AP4=$AP3,$AJ5<>"t"),BG4,CF4) -> 0.31458333 | BH5: =IF(AND($AM4=$AM3,$AN4=AN3,$AO4=$AO3,$AP4=$AP3,$AJ5<>"t"),BH4,CG4) -> 0.31388889 | BI5: =AI5-AZ5 -> 0.02 | BJ5: =IF($AJ4="t",IF(AM3=0,0,$BI5/AM3),IF(AM4=0,0,$BI5/AM4)) -> 0.00066666667 | BK5: =IF($AJ4="t",IF(AN3=0,0,$BI5/AN3),IF(AN4=0,0,$BI5/AN4)) -> 0.00066666667 | BL5: =IF($AJ4="t",IF(AO3=0,0,$BI5/AO3),IF(AO4=0,0,$BI5/AO4)) -> 0.00066666667 | BM5: =IF($AJ4="t",IF(AP3=0,0,$BI5/AP3),IF(AP4=0,0,$BI5/AP4)) -> 0.00066666667 | BN5: =IF(AJ5="t",0,INT(BJ5)) -> 0 | BO5: =IF(AJ5="t",AM5,IF(INT((BJ5-BN5)*60)<0,1,INT((BJ5-BN5)*60))) -> 0 | BP5: =IF(AJ5="t",0,ROUND((((BJ5-BN5)*60)-BO5)*60,0)) -> 2 | BQ5: =IF(AJ5="t",0,INT(BK5)) -> 0 | BR5: =IF(AJ5="t",AN5,IF(INT((BK5-BQ5)*60)<0,1,INT((BK5-BQ5)*60))) -> 0 | BS5: =IF(AJ5="t",0,ROUND((((BK5-BQ5)*60)-BR5)*60,0)) -> 2 | BT5: =IF(AJ5="t",0,INT(BL5)) -> 0 | BU5: =IF(AJ5="t",AO5,IF(INT((BL5-BT5)*60)<0,1,INT((BL5-BT5)*60))) -> 0 | BV5: =IF(AJ5="t",0,ROUND((((BL5-BT5)*60)-BU5)*60,0)) -> 2 | BW5: =IF(AJ5="t",0,INT(BM5)) -> 0 | BX5: =IF(AJ5="t",AP5,IF(INT((BM5-BW5)*60)<0,1,INT((BM5-BW5)*60))) -> 0 | BY5: =IF(AJ5="t",0,ROUND((((BM5-BW5)*60)-BX5)*60,0)) -> 2 | BZ5: =BA5+TIME(BN5,BO5,BP5) -> 0.25071759 | CA5: =BB5+TIME(BN5,BO5,BP5) -> 0.25627315 | CB5: =BC5+TIME(BQ5,BR5,BS5) -> 0.25696759 | CC5: =BD5+TIME(BQ5,BR5,BS5) -> 0.30280093 | CD5: =BE5+TIME(BT5,BU5,BV5) -> 0.30349537 | CE5: =BF5+TIME(BT5,BU5,BV5) -> 0.31391204 | CF5: =BG5+TIME(BW5,BX5,BY5) -> 0.31460648 | CG5: =BH5+TIME(BW5,BX5,BY5) -> 0.31391204 | CL5: 60
A6: 26 | C6: o | D6: 30 | G6: 0.16 | H6: =ROUND(IF(G6="",N6,IF(P6="",I6,IF(R6="",(I6+(P6+O6))/2,IF(T6="",(I6+(P6+O6)+(R6+Q6))/3,(I6+(P6+O6)+(R6+Q6)+(T6+S6))/4)))),2) -> 0.17 | I6: 0.16 | J6: =IF(N6="","",IF((I6-$I$4)=0,0,((I6-$I$4-(N6-$N$4))/(I6-$I$4)))) -> -0.041666667 | K6: =(I6-$I$5)-(N6-$N$5) -> -0.0066666667 | L6: Traffic Light Carry Straight On | M6: 60 | N6: =IF(P6="",((I6-I5)+H5),IF(R6="",(P6+O6),IF(T6="",((P6+O6)+(R6+Q6))/2,((P6+O6)+(R6+Q6)+(T6+S6))/3))) -> 0.16666667 | P6: 0.17 | R6: 0.16 | T6: 0.17 | U6: =IF(W6="","",IF(Y6="",W6,IF(AA6<1,ROUND((Y6+W6)/2,5),IF(AC6<1,ROUND((Y6+AA6+W6)/3,5),ROUND((Y6+AA6+AC6+W6)/4,5))))) | V6: =IF(X6="","",IF(Z6<1,ROUND(X6,5),IF(AB6<1,ROUND((X6+Z6)/2,5),IF(AD6<1,ROUND((X6+Z6+AB6)/3,5),ROUND((X6+Z6+AB6+AD6)/4,5))))) | AE6: =IF(A6="","",A6) -> 26 | AF6: =IF(B6="","",B6) | AG6: =IF(C6="","",C6) -> o | AH6: =IF(D6="","",D6) -> 30 | AI6: =H6 -> 0.17 | AJ6: o | AM6: =IF(OR(AJ6="",AJ6="m"),AM5,IF(AH6<>"",AH6,"")) -> 30 | AN6: =IF(AJ6<>"",IF(AJ6="o",VLOOKUP(AM6,OpenSect!$A$1:$D$11,2),IF(AJ6="u",VLOOKUP(AM6,UpHill!$A$1:$D$35,2),IF(AJ6="d",VLOOKUP(AM6,DownHill!$A$3:$D$29,2),IF(AJ6="f",VLOOKUP(AM6,FlatUnd!$A$2:$D$30,2),IF(AJ6="t",VLOOKUP(AM6,TimeAdd!$A$1:$D$176,2),IF(AJ6="l",VLOOKUP(AM6,SLimit!$A$1:$D$8,2),AN5)))))),AN5) -> 30 | AO6: =IF(AJ6<>"",IF(AJ6="o",VLOOKUP(AM6,OpenSect!$A$1:$D$11,3),IF(AJ6="u",VLOOKUP(AM6,UpHill!$A$1:$D$35,3),IF(AJ6="d",VLOOKUP(AM6,DownHill!$A$3:$D$29,3),IF(AJ6="f",VLOOKUP(AM6,FlatUnd!$A$2:$D$30,3),IF(AJ6="t",VLOOKUP(AM6,TimeAdd!$A$1:$D$18,3),IF(AJ6="l",VLOOKUP(AM6,SLimit!$A$1:$D$8,3),AO5)))))),AO5) -> 30 | AP6: =IF(AJ6<>"",IF(AJ6="o",VLOOKUP(AM6,OpenSect!$A$1:$D$11,4),IF(AJ6="u",VLOOKUP(AM6,UpHill!$A$1:$D$35,4),IF(AJ6="d",VLOOKUP(AM6,DownHill!$A$3:$D$29,4),IF(AJ6="f",VLOOKUP(AM6,FlatUnd!$A$2:$D$30,4),IF(AJ6="t",VLOOKUP(AM6,TimeAdd!$A$1:$D$18,4),IF(AJ6="l",VLOOKUP(AM6,SLimit!$A$1:$D$8,4),AP5)))))),AP5) -> 30 | AQ6: =M6 -> 60 | AR6: =L6 -> Traffic Light Carry Straight On | AU6: =IF(GroupStTimes!$A$8=0,MIN(CB6,CD6,CF6),MIN(BZ6,CB6,CD6,CF6)) -> 0.25092593 | AV6: =IF(GroupStTimes!$A$8=0,MAX(CC6,CE6,CG6),MAX(CA6,CC6,CE6,CG6)) -> 0.31412037 | AW6: =IF(U6="","",CONCATENATE(FIXED(U6,5)," ",FIXED(V6,5))) | AX6: =IF(AJ6="m",ROUND(W6,5),"") | AY6: =IF(AJ6="m",ROUND(X6,5),"") | AZ6: =IF(AND(AM5=AM4,AN5=AN4,AO5=AO4,AP5=AP4,AJ6<>"t"),AZ5,IF(AJ6="t",AI6,AI5)) -> 0 | BA6: =IF(AND($AM5=$AM4,$AN5=AN4,$AO5=$AO4,$AP5=$AP4,$AJ6<>"t"),BA5,BZ5) -> 0.25069444 | BB6: =IF(AND($AM5=$AM4,$AN5=AN4,$AO5=$AO4,$AP5=$AP4,$AJ6<>"t"),BB5,CA5) -> 0.25625 | BC6: =IF(AND($AM5=$AM4,$AN5=AN4,$AO5=$AO4,$AP5=$AP4,$AJ6<>"t"),BC5,CB5) -> 0.25694444 | BD6: =IF(AND($AM5=$AM4,$AN5=AN4,$AO5=$AO4,$AP5=$AP4,$AJ6<>"t"),BD5,CC5) -> 0.30277778 | BE6: =IF(AND($AM5=$AM4,$AN5=AN4,$AO5=$AO4,$AP5=$AP4,$AJ6<>"t"),BE5,CD5) -> 0.30347222 | BF6: =IF(AND($AM5=$AM4,$AN5=AN4,$AO5=$AO4,$AP5=$AP4,$AJ6<>"t"),BF5,CE5) -> 0.31388889 | BG6: =IF(AND($AM5=$AM4,$AN5=AN4,$AO5=$AO4,$AP5=$AP4,$AJ6<>"t"),BG5,CF5) -> 0.31458333 | BH6: =IF(AND($AM5=$AM4,$AN5=AN4,$AO5=$AO4,$AP5=$AP4,$AJ6<>"t"),BH5,CG5) -> 0.31388889 | BI6: =AI6-AZ6 -> 0.17 | BJ6: =IF($AJ5="t",IF(AM4=0,0,$BI6/AM4),IF(AM5=0,0,$BI6/AM5)) -> 0.0056666667 | BK6: =IF($AJ5="t",IF(AN4=0,0,$BI6/AN4),IF(AN5=0,0,$BI6/AN5)) -> 0.0056666667 | BL6: =IF($AJ5="t",IF(AO4=0,0,$BI6/AO4),IF(AO5=0,0,$BI6/AO5)) -> 0.0056666667 | BM6: =IF($AJ5="t",IF(AP4=0,0,$BI6/AP4),IF(AP5=0,0,$BI6/AP5)) -> 0.0056666667 | BN6: =IF(AJ6="t",0,INT(BJ6)) -> 0 | BO6: =IF(AJ6="t",AM6,IF(INT((BJ6-BN6)*60)<0,1,INT((BJ6-BN6)*60))) -> 0 | BP6: =IF(AJ6="t",0,ROUND((((BJ6-BN6)*60)-BO6)*60,0)) -> 20 | BQ6: =IF(AJ6="t",0,INT(BK6)) -> 0 | BR6: =IF(AJ6="t",AN6,IF(INT((BK6-BQ6)*60)<0,1,INT((BK6-BQ6)*60))) -> 0 | BS6: =IF(AJ6="t",0,ROUND((((BK6-BQ6)*60)-BR6)*60,0)) -> 20 | BT6: =IF(AJ6="t",0,INT(BL6)) -> 0 | BU6: =IF(AJ6="t",AO6,IF(INT((BL6-BT6)*60)<0,1,INT((BL6-BT6)*60))) -> 0 | BV6: =IF(AJ6="t",0,ROUND((((BL6-BT6)*60)-BU6)*60,0)) -> 20 | BW6: =IF(AJ6="t",0,INT(BM6)) -> 0 | BX6: =IF(AJ6="t",AP6,IF(INT((BM6-BW6)*60)<0,1,INT((BM6-BW6)*60))) -> 0 | BY6: =IF(AJ6="t",0,ROUND((((BM6-BW6)*60)-BX6)*60,0)) -> 20 | BZ6: =BA6+TIME(BN6,BO6,BP6) -> 0.25092593 | CA6: =BB6+TIME(BN6,BO6,BP6) -> 0.25648148 | CB6: =BC6+TIME(BQ6,BR6,BS6) -> 0.25717593 | CC6: =BD6+TIME(BQ6,BR6,BS6) -> 0.30300926 | CD6: =BE6+TIME(BT6,BU6,BV6) -> 0.3037037 | CE6: =BF6+TIME(BT6,BU6,BV6) -> 0.31412037 | CF6: =BG6+TIME(BW6,BX6,BY6) -> 0.31481481 | CG6: =BH6+TIME(BW6,BX6,BY6) -> 0.31412037 | CL6: 60
A7: 26 | C7: o | D7: 30 | G7: 0.31 | H7: =ROUND(IF(G7="",N7,IF(P7="",I7,IF(R7="",(I7+(P7+O7))/2,IF(T7="",(I7+(P7+O7)+(R7+Q7))/3,(I7+(P7+O7)+(R7+Q7)+(T7+S7))/4)))),2) -> 0.32 | I7: 0.31 | J7: =IF(N7="","",IF((I7-$I$4)=0,0,((I7-$I$4-(N7-$N$4))/(I7-$I$4)))) -> -0.021505376 | K7: =(I7-$I$5)-(N7-$N$5) -> -0.0066666667 | L7: Traffic Light Carry Straight On | M7: 60 | N7: =IF(P7="",((I7-I6)+H6),IF(R7="",(P7+O7),IF(T7="",((P7+O7)+(R7+Q7))/2,((P7+O7)+(R7+Q7)+(T7+S7))/3))) -> 0.31666667 | P7: 0.32 | R7: 0.31 | T7: 0.32 | U7: =IF(W7="","",IF(Y7="",W7,IF(AA7<1,ROUND((Y7+W7)/2,5),IF(AC7<1,ROUND((Y7+AA7+W7)/3,5),ROUND((Y7+AA7+AC7+W7)/4,5))))) | V7: =IF(X7="","",IF(Z7<1,ROUND(X7,5),IF(AB7<1,ROUND((X7+Z7)/2,5),IF(AD7<1,ROUND((X7+Z7+AB7)/3,5),ROUND((X7+Z7+AB7+AD7)/4,5))))) | AE7: =IF(A7="","",A7) -> 26 | AF7: =IF(B7="","",B7) | AG7: =IF(C7="","",C7) -> o | AH7: =IF(D7="","",D7) -> 30 | AI7: =H7 -> 0.32 | AJ7: o | AM7: =IF(OR(AJ7="",AJ7="m"),AM6,IF(AH7<>"",AH7,"")) -> 30 | AN7: =IF(AJ7<>"",IF(AJ7="o",VLOOKUP(AM7,OpenSect!$A$1:$D$11,2),IF(AJ7="u",VLOOKUP(AM7,UpHill!$A$1:$D$35,2),IF(AJ7="d",VLOOKUP(AM7,DownHill!$A$3:$D$29,2),IF(AJ7="f",VLOOKUP(AM7,FlatUnd!$A$2:$D$30,2),IF(AJ7="t",VLOOKUP(AM7,TimeAdd!$A$1:$D$176,2),IF(AJ7="l",VLOOKUP(AM7,SLimit!$A$1:$D$8,2),AN6)))))),AN6) -> 30 | AO7: =IF(AJ7<>"",IF(AJ7="o",VLOOKUP(AM7,OpenSect!$A$1:$D$11,3),IF(AJ7="u",VLOOKUP(AM7,UpHill!$A$1:$D$35,3),IF(AJ7="d",VLOOKUP(AM7,DownHill!$A$3:$D$29,3),IF(AJ7="f",VLOOKUP(AM7,FlatUnd!$A$2:$D$30,3),IF(AJ7="t",VLOOKUP(AM7,TimeAdd!$A$1:$D$18,3),IF(AJ7="l",VLOOKUP(AM7,SLimit!$A$1:$D$8,3),AO6)))))),AO6) -> 30 | AP7: =IF(AJ7<>"",IF(AJ7="o",VLOOKUP(AM7,OpenSect!$A$1:$D$11,4),IF(AJ7="u",VLOOKUP(AM7,UpHill!$A$1:$D$35,4),IF(AJ7="d",VLOOKUP(AM7,DownHill!$A$3:$D$29,4),IF(AJ7="f",VLOOKUP(AM7,FlatUnd!$A$2:$D$30,4),IF(AJ7="t",VLOOKUP(AM7,TimeAdd!$A$1:$D$18,4),IF(AJ7="l",VLOOKUP(AM7,SLimit!$A$1:$D$8,4),AP6)))))),AP6) -> 30 | AQ7: =M7 -> 60 | AR7: =L7 -> Traffic Light Carry Straight On | AU7: =IF(GroupStTimes!$A$8=0,MIN(CB7,CD7,CF7),MIN(BZ7,CB7,CD7,CF7)) -> 0.25113426 | AV7: =IF(GroupStTimes!$A$8=0,MAX(CC7,CE7,CG7),MAX(CA7,CC7,CE7,CG7)) -> 0.3143287 | AW7: =IF(U7="","",CONCATENATE(FIXED(U7,5)," ",FIXED(V7,5))) | AX7: =IF(AJ7="m",ROUND(W7,5),"") | AY7: =IF(AJ7="m",ROUND(X7,5),"") | AZ7: =IF(AND(AM6=AM5,AN6=AN5,AO6=AO5,AP6=AP5,AJ7<>"t"),AZ6,IF(AJ7="t",AI7,AI6)) -> 0 | BA7: =IF(AND($AM6=$AM5,$AN6=AN5,$AO6=$AO5,$AP6=$AP5,$AJ7<>"t"),BA6,BZ6) -> 0.25069444 | BB7: =IF(AND($AM6=$AM5,$AN6=AN5,$AO6=$AO5,$AP6=$AP5,$AJ7<>"t"),BB6,CA6) -> 0.25625 | BC7: =IF(AND($AM6=$AM5,$AN6=AN5,$AO6=$AO5,$AP6=$AP5,$AJ7<>"t"),BC6,CB6) -> 0.25694444 | BD7: =IF(AND($AM6=$AM5,$AN6=AN5,$AO6=$AO5,$AP6=$AP5,$AJ7<>"t"),BD6,CC6) -> 0.30277778 | BE7: =IF(AND($AM6=$AM5,$AN6=AN5,$AO6=$AO5,$AP6=$AP5,$AJ7<>"t"),BE6,CD6) -> 0.30347222 | BF7: =IF(AND($AM6=$AM5,$AN6=AN5,$AO6=$AO5,$AP6=$AP5,$AJ7<>"t"),BF6,CE6) -> 0.31388889 | BG7: =IF(AND($AM6=$AM5,$AN6=AN5,$AO6=$AO5,$AP6=$AP5,$AJ7<>"t"),BG6,CF6) -> 0.31458333 | BH7: =IF(AND($AM6=$AM5,$AN6=AN5,$AO6=$AO5,$AP6=$AP5,$AJ7<>"t"),BH6,CG6) -> 0.31388889 | BI7: =AI7-AZ7 -> 0.32 | BJ7: =IF($AJ6="t",IF(AM5=0,0,$BI7/AM5),IF(AM6=0,0,$BI7/AM6)) -> 0.010666667 | BK7: =IF($AJ6="t",IF(AN5=0,0,$BI7/AN5),IF(AN6=0,0,$BI7/AN6)) -> 0.010666667 | BL7: =IF($AJ6="t",IF(AO5=0,0,$BI7/AO5),IF(AO6=0,0,$BI7/AO6)) -> 0.010666667 | BM7: =IF($AJ6="t",IF(AP5=0,0,$BI7/AP5),IF(AP6=0,0,$BI7/AP6)) -> 0.010666667 | BN7: =IF(AJ7="t",0,INT(BJ7)) -> 0 | BO7: =IF(AJ7="t",AM7,IF(INT((BJ7-BN7)*60)<0,1,INT((BJ7-BN7)*60))) -> 0 | BP7: =IF(AJ7="t",0,ROUND((((BJ7-BN7)*60)-BO7)*60,0)) -> 38 | BQ7: =IF(AJ7="t",0,INT(BK7)) -> 0 | BR7: =IF(AJ7="t",AN7,IF(INT((BK7-BQ7)*60)<0,1,INT((BK7-BQ7)*60))) -> 0 | BS7: =IF(AJ7="t",0,ROUND((((BK7-BQ7)*60)-BR7)*60,0)) -> 38 | BT7: =IF(AJ7="t",0,INT(BL7)) -> 0 | BU7: =IF(AJ7="t",AO7,IF(INT((BL7-BT7)*60)<0,1,INT((BL7-BT7)*60))) -> 0 | BV7: =IF(AJ7="t",0,ROUND((((BL7-BT7)*60)-BU7)*60,0)) -> 38 | BW7: =IF(AJ7="t",0,INT(BM7)) -> 0 | BX7: =IF(AJ7="t",AP7,IF(INT((BM7-BW7)*60)<0,1,INT((BM7-BW7)*60))) -> 0 | BY7: =IF(AJ7="t",0,ROUND((((BM7-BW7)*60)-BX7)*60,0)) -> 38 | BZ7: =BA7+TIME(BN7,BO7,BP7) -> 0.25113426 | CA7: =BB7+TIME(BN7,BO7,BP7) -> 0.25668981 | CB7: =BC7+TIME(BQ7,BR7,BS7) -> 0.25738426 | CC7: =BD7+TIME(BQ7,BR7,BS7) -> 0.30321759 | CD7: =BE7+TIME(BT7,BU7,BV7) -> 0.30391204 | CE7: =BF7+TIME(BT7,BU7,BV7) -> 0.3143287 | CF7: =BG7+TIME(BW7,BX7,BY7) -> 0.31502315 | CG7: =BH7+TIME(BW7,BX7,BY7) -> 0.3143287 | CL7: 60
A8: 26 | G8: 0.57 | H8: =ROUND(IF(G8="",N8,IF(P8="",I8,IF(R8="",(I8+(P8+O8))/2,IF(T8="",(I8+(P8+O8)+(R8+Q8))/3,(I8+(P8+O8)+(R8+Q8)+(T8+S8))/4)))),2) -> 0.57 | I8: 0.57 | J8: =IF(N8="","",IF((I8-$I$4)=0,0,((I8-$I$4-(N8-$N$4))/(I8-$I$4)))) -> 0 | K8: =(I8-$I$5)-(N8-$N$5) -> 0 | L8: R103. Bothas Hill 5 | M8: 60 | N8: =IF(P8="",((I8-I7)+H7),IF(R8="",(P8+O8),IF(T8="",((P8+O8)+(R8+Q8))/2,((P8+O8)+(R8+Q8)+(T8+S8))/3))) -> 0.57 | P8: 0.57 | R8: 0.57 | T8: 0.57 | U8: =IF(W8="","",IF(Y8="",W8,IF(AA8<1,ROUND((Y8+W8)/2,5),IF(AC8<1,ROUND((Y8+AA8+W8)/3,5),ROUND((Y8+AA8+AC8+W8)/4,5))))) | V8: =IF(X8="","",IF(Z8<1,ROUND(X8,5),IF(AB8<1,ROUND((X8+Z8)/2,5),IF(AD8<1,ROUND((X8+Z8+AB8)/3,5),ROUND((X8+Z8+AB8+AD8)/4,5))))) | AE8: =IF(A8="","",A8) -> 26 | AF8: =IF(B8="","",B8) | AG8: =IF(C8="","",C8) | AH8: =IF(D8="","",D8) | AI8: =H8 -> 0.57 | AM8: =IF(OR(AJ8="",AJ8="m"),AM7,IF(AH8<>"",AH8,"")) -> 30 | AN8: =IF(AJ8<>"",IF(AJ8="o",VLOOKUP(AM8,OpenSect!$A$1:$D$11,2),IF(AJ8="u",VLOOKUP(AM8,UpHill!$A$1:$D$35,2),IF(AJ8="d",VLOOKUP(AM8,DownHill!$A$3:$D$29,2),IF(AJ8="f",VLOOKUP(AM8,FlatUnd!$A$2:$D$30,2),IF(AJ8="t",VLOOKUP(AM8,TimeAdd!$A$1:$D$176,2),IF(AJ8="l",VLOOKUP(AM8,SLimit!$A$1:$D$8,2),AN7)))))),AN7) -> 30 | AO8: =IF(AJ8<>"",IF(AJ8="o",VLOOKUP(AM8,OpenSect!$A$1:$D$11,3),IF(AJ8="u",VLOOKUP(AM8,UpHill!$A$1:$D$35,3),IF(AJ8="d",VLOOKUP(AM8,DownHill!$A$3:$D$29,3),IF(AJ8="f",VLOOKUP(AM8,FlatUnd!$A$2:$D$30,3),IF(AJ8="t",VLOOKUP(AM8,TimeAdd!$A$1:$D$18,3),IF(AJ8="l",VLOOKUP(AM8,SLimit!$A$1:$D$8,3),AO7)))))),AO7) -> 30 | AP8: =IF(AJ8<>"",IF(AJ8="o",VLOOKUP(AM8,OpenSect!$A$1:$D$11,4),IF(AJ8="u",VLOOKUP(AM8,UpHill!$A$1:$D$35,4),IF(AJ8="d",VLOOKUP(AM8,DownHill!$A$3:$D$29,4),IF(AJ8="f",VLOOKUP(AM8,FlatUnd!$A$2:$D$30,4),IF(AJ8="t",VLOOKUP(AM8,TimeAdd!$A$1:$D$18,4),IF(AJ8="l",VLOOKUP(AM8,SLimit!$A$1:$D$8,4),AP7)))))),AP7) -> 30 | AQ8: =M8 -> 60 | AR8: =L8 -> R103. Bothas Hill 5 | AU8: =IF(GroupStTimes!$A$8=0,MIN(CB8,CD8,CF8),MIN(BZ8,CB8,CD8,CF8)) -> 0.25148148 | AV8: =IF(GroupStTimes!$A$8=0,MAX(CC8,CE8,CG8),MAX(CA8,CC8,CE8,CG8)) -> 0.31467593 | AW8: =IF(U8="","",CONCATENATE(FIXED(U8,5)," ",FIXED(V8,5))) | AX8: =IF(AJ8="m",ROUND(W8,5),"") | AY8: =IF(AJ8="m",ROUND(X8,5),"") | AZ8: =IF(AND(AM7=AM6,AN7=AN6,AO7=AO6,AP7=AP6,AJ8<>"t"),AZ7,IF(AJ8="t",AI8,AI7)) -> 0 | BA8: =IF(AND($AM7=$AM6,$AN7=AN6,$AO7=$AO6,$AP7=$AP6,$AJ8<>"t"),BA7,BZ7) -> 0.25069444 | BB8: =IF(AND($AM7=$AM6,$AN7=AN6,$AO7=$AO6,$AP7=$AP6,$AJ8<>"t"),BB7,CA7) -> 0.25625 | BC8: =IF(AND($AM7=$AM6,$AN7=AN6,$AO7=$AO6,$AP7=$AP6,$AJ8<>"t"),BC7,CB7) -> 0.25694444 | BD8: =IF(AND($AM7=$AM6,$AN7=AN6,$AO7=$AO6,$AP7=$AP6,$AJ8<>"t"),BD7,CC7) -> 0.30277778 | BE8: =IF(AND($AM7=$AM6,$AN7=AN6,$AO7=$AO6,$AP7=$AP6,$AJ8<>"t"),BE7,CD7) -> 0.30347222 | BF8: =IF(AND($AM7=$AM6,$AN7=AN6,$AO7=$AO6,$AP7=$AP6,$AJ8<>"t"),BF7,CE7) -> 0.31388889 | BG8: =IF(AND($AM7=$AM6,$AN7=AN6,$AO7=$AO6,$AP7=$AP6,$AJ8<>"t"),BG7,CF7) -> 0.31458333 | BH8: =IF(AND($AM7=$AM6,$AN7=AN6,$AO7=$AO6,$AP7=$AP6,$AJ8<>"t"),BH7,CG7) -> 0.31388889 | BI8: =AI8-AZ8 -> 0.57 | BJ8: =IF($AJ7="t",IF(AM6=0,0,$BI8/AM6),IF(AM7=0,0,$BI8/AM7)) -> 0.019 | BK8: =IF($AJ7="t",IF(AN6=0,0,$BI8/AN6),IF(AN7=0,0,$BI8/AN7)) -> 0.019 | BL8: =IF($AJ7="t",IF(AO6=0,0,$BI8/AO6),IF(AO7=0,0,$BI8/AO7)) -> 0.019 | BM8: =IF($AJ7="t",IF(AP6=0,0,$BI8/AP6),IF(AP7=0,0,$BI8/AP7)) -> 0.019 | BN8: =IF(AJ8="t",0,INT(BJ8)) -> 0 | BO8: =IF(AJ8="t",AM8,IF(INT((BJ8-BN8)*60)<0,1,INT((BJ8-BN8)*60))) -> 1 | BP8: =IF(AJ8="t",0,ROUND((((BJ8-BN8)*60)-BO8)*60,0)) -> 8 | BQ8: =IF(AJ8="t",0,INT(BK8)) -> 0 | BR8: =IF(AJ8="t",AN8,IF(INT((BK8-BQ8)*60)<0,1,INT((BK8-BQ8)*60))) -> 1 | BS8: =IF(AJ8="t",0,ROUND((((BK8-BQ8)*60)-BR8)*60,0)) -> 8 | BT8: =IF(AJ8="t",0,INT(BL8)) -> 0 | BU8: =IF(AJ8="t",AO8,IF(INT((BL8-BT8)*60)<0,1,INT((BL8-BT8)*60))) -> 1 | BV8: =IF(AJ8="t",0,ROUND((((BL8-BT8)*60)-BU8)*60,0)) -> 8 | BW8: =IF(AJ8="t",0,INT(BM8)) -> 0 | BX8: =IF(AJ8="t",AP8,IF(INT((BM8-BW8)*60)<0,1,INT((BM8-BW8)*60))) -> 1 | BY8: =IF(AJ8="t",0,ROUND((((BM8-BW8)*60)-BX8)*60,0)) -> 8 | BZ8: =BA8+TIME(BN8,BO8,BP8) -> 0.25148148 | CA8: =BB8+TIME(BN8,BO8,BP8) -> 0.25703704 | CB8: =BC8+TIME(BQ8,BR8,BS8) -> 0.25773148 | CC8: =BD8+TIME(BQ8,BR8,BS8) -> 0.30356481 | CD8: =BE8+TIME(BT8,BU8,BV8) -> 0.30425926 | CE8: =BF8+TIME(BT8,BU8,BV8) -> 0.31467593 | CF8: =BG8+TIME(BW8,BX8,BY8) -> 0.31537037 | CG8: =BH8+TIME(BW8,BX8,BY8) -> 0.31467593 | CL8: 60
A9: 26 | G9: 1.24 | H9: =ROUND(IF(G9="",N9,IF(P9="",I9,IF(R9="",(I9+(P9+O9))/2,IF(T9="",(I9+(P9+O9)+(R9+Q9))/3,(I9+(P9+O9)+(R9+Q9)+(T9+S9))/4)))),2) -> 1.24 | I9: 1.23 | J9: =IF(N9="","",IF((I9-$I$4)=0,0,((I9-$I$4-(N9-$N$4))/(I9-$I$4)))) -> -0.0054200542 | K9: =(I9-$I$5)-(N9-$N$5) -> -0.0066666667 | L9: Kassier Road {Right} Assegai (N3). [Toll] [Freeway] 32. | M9: 60 | N9: =IF(P9="",((I9-I8)+H8),IF(R9="",(P9+O9),IF(T9="",((P9+O9)+(R9+Q9))/2,((P9+O9)+(R9+Q9)+(T9+S9))/3))) -> 1.2366667 | P9: 1.23 | R9: 1.24 | T9: 1.24 | U9: =IF(W9="","",IF(Y9="",W9,IF(AA9<1,ROUND((Y9+W9)/2,5),IF(AC9<1,ROUND((Y9+AA9+W9)/3,5),ROUND((Y9+AA9+AC9+W9)/4,5))))) | V9: =IF(X9="","",IF(Z9<1,ROUND(X9,5),IF(AB9<1,ROUND((X9+Z9)/2,5),IF(AD9<1,ROUND((X9+Z9+AB9)/3,5),ROUND((X9+Z9+AB9+AD9)/4,5))))) | AE9: =IF(A9="","",A9) -> 26 | AF9: =IF(B9="","",B9) | AG9: =IF(C9="","",C9) | AH9: =IF(D9="","",D9) | AI9: =H9 -> 1.24 | AM9: =IF(OR(AJ9="",AJ9="m"),AM8,IF(AH9<>"",AH9,"")) -> 30 | AN9: =IF(AJ9<>"",IF(AJ9="o",VLOOKUP(AM9,OpenSect!$A$1:$D$11,2),IF(AJ9="u",VLOOKUP(AM9,UpHill!$A$1:$D$35,2),IF(AJ9="d",VLOOKUP(AM9,DownHill!$A$3:$D$29,2),IF(AJ9="f",VLOOKUP(AM9,FlatUnd!$A$2:$D$30,2),IF(AJ9="t",VLOOKUP(AM9,TimeAdd!$A$1:$D$176,2),IF(AJ9="l",VLOOKUP(AM9,SLimit!$A$1:$D$8,2),AN8)))))),AN8) -> 30 | AO9: =IF(AJ9<>"",IF(AJ9="o",VLOOKUP(AM9,OpenSect!$A$1:$D$11,3),IF(AJ9="u",VLOOKUP(AM9,UpHill!$A$1:$D$35,3),IF(AJ9="d",VLOOKUP(AM9,DownHill!$A$3:$D$29,3),IF(AJ9="f",VLOOKUP(AM9,FlatUnd!$A$2:$D$30,3),IF(AJ9="t",VLOOKUP(AM9,TimeAdd!$A$1:$D$18,3),IF(AJ9="l",VLOOKUP(AM9,SLimit!$A$1:$D$8,3),AO8)))))),AO8) -> 30 | AP9: =IF(AJ9<>"",IF(AJ9="o",VLOOKUP(AM9,OpenSect!$A$1:$D$11,4),IF(AJ9="u",VLOOKUP(AM9,UpHill!$A$1:$D$35,4),IF(AJ9="d",VLOOKUP(AM9,DownHill!$A$3:$D$29,4),IF(AJ9="f",VLOOKUP(AM9,FlatUnd!$A$2:$D$30,4),IF(AJ9="t",VLOOKUP(AM9,TimeAdd!$A$1:$D$18,4),IF(AJ9="l",VLOOKUP(AM9,SLimit!$A$1:$D$8,4),AP8)))))),AP8) -> 30 | AQ9: =M9 -> 60 | AR9: =L9 -> Kassier Road {Right} Assegai (N3). [Toll] [Freeway] 32. | AU9: =IF(GroupStTimes!$A$8=0,MIN(CB9,CD9,CF9),MIN(BZ9,CB9,CD9,CF9)) -> 0.25241898 | AV9: =IF(GroupStTimes!$A$8=0,MAX(CC9,CE9,CG9),MAX(CA9,CC9,CE9,CG9)) -> 0.31561343 | AW9: =IF(U9="","",CONCATENATE(FIXED(U9,5)," ",FIXED(V9,5))) | AX9: =IF(AJ9="m",ROUND(W9,5),"") | AY9: =IF(AJ9="m",ROUND(X9,5),"") | AZ9: =IF(AND(AM8=AM7,AN8=AN7,AO8=AO7,AP8=AP7,AJ9<>"t"),AZ8,IF(AJ9="t",AI9,AI8)) -> 0 | BA9: =IF(AND($AM8=$AM7,$AN8=AN7,$AO8=$AO7,$AP8=$AP7,$AJ9<>"t"),BA8,BZ8) -> 0.25069444 | BB9: =IF(AND($AM8=$AM7,$AN8=AN7,$AO8=$AO7,$AP8=$AP7,$AJ9<>"t"),BB8,CA8) -> 0.25625 | BC9: =IF(AND($AM8=$AM7,$AN8=AN7,$AO8=$AO7,$AP8=$AP7,$AJ9<>"t"),BC8,CB8) -> 0.25694444 | BD9: =IF(AND($AM8=$AM7,$AN8=AN7,$AO8=$AO7,$AP8=$AP7,$AJ9<>"t"),BD8,CC8) -> 0.30277778 | BE9: =IF(AND($AM8=$AM7,$AN8=AN7,$AO8=$AO7,$AP8=$AP7,$AJ9<>"t"),BE8,CD8) -> 0.30347222 | BF9: =IF(AND($AM8=$AM7,$AN8=AN7,$AO8=$AO7,$AP8=$AP7,$AJ9<>"t"),BF8,CE8) -> 0.31388889 | BG9: =IF(AND($AM8=$AM7,$AN8=AN7,$AO8=$AO7,$AP8=$AP7,$AJ9<>"t"),BG8,CF8) -> 0.31458333 | BH9: =IF(AND($AM8=$AM7,$AN8=AN7,$AO8=$AO7,$AP8=$AP7,$AJ9<>"t"),BH8,CG8) -> 0.31388889 | BI9: =AI9-AZ9 -> 1.24 | BJ9: =IF($AJ8="t",IF(AM7=0,0,$BI9/AM7),IF(AM8=0,0,$BI9/AM8)) -> 0.041333333 | BK9: =IF($AJ8="t",IF(AN7=0,0,$BI9/AN7),IF(AN8=0,0,$BI9/AN8)) -> 0.041333333 | BL9: =IF($AJ8="t",IF(AO7=0,0,$BI9/AO7),IF(AO8=0,0,$BI9/AO8)) -> 0.041333333 | BM9: =IF($AJ8="t",IF(AP7=0,0,$BI9/AP7),IF(AP8=0,0,$BI9/AP8)) -> 0.041333333 | BN9: =IF(AJ9="t",0,INT(BJ9)) -> 0 | BO9: =IF(AJ9="t",AM9,IF(INT((BJ9-BN9)*60)<0,1,INT((BJ9-BN9)*60))) -> 2 | BP9: =IF(AJ9="t",0,ROUND((((BJ9-BN9)*60)-BO9)*60,0)) -> 29 | BQ9: =IF(AJ9="t",0,INT(BK9)) -> 0 | BR9: =IF(AJ9="t",AN9,IF(INT((BK9-BQ9)*60)<0,1,INT((BK9-BQ9)*60))) -> 2 | BS9: =IF(AJ9="t",0,ROUND((((BK9-BQ9)*60)-BR9)*60,0)) -> 29 | BT9: =IF(AJ9="t",0,INT(BL9)) -> 0 | BU9: =IF(AJ9="t",AO9,IF(INT((BL9-BT9)*60)<0,1,INT((BL9-BT9)*60))) -> 2 | BV9: =IF(AJ9="t",0,ROUND((((BL9-BT9)*60)-BU9)*60,0)) -> 29 | BW9: =IF(AJ9="t",0,INT(BM9)) -> 0 | BX9: =IF(AJ9="t",AP9,IF(INT((BM9-BW9)*60)<0,1,INT((BM9-BW9)*60))) -> 2 | BY9: =IF(AJ9="t",0,ROUND((((BM9-BW9)*60)-BX9)*60,0)) -> 29 | BZ9: =BA9+TIME(BN9,BO9,BP9) -> 0.25241898 | CA9: =BB9+TIME(BN9,BO9,BP9) -> 0.25797454 | CB9: =BC9+TIME(BQ9,BR9,BS9) -> 0.25866898 | CC9: =BD9+TIME(BQ9,BR9,BS9) -> 0.30450231 | CD9: =BE9+TIME(BT9,BU9,BV9) -> 0.30519676 | CE9: =BF9+TIME(BT9,BU9,BV9) -> 0.31561343 | CF9: =BG9+TIME(BW9,BX9,BY9) -> 0.31630787 | CG9: =BH9+TIME(BW9,BX9,BY9) -> 0.31561343 | CL9: 60
A10: 26 | C10: l | D10: 30 | G10: 1.25 | H10: =ROUND(IF(G10="",N10,IF(P10="",I10,IF(R10="",(I10+(P10+O10))/2,IF(T10="",(I10+(P10+O10)+(R10+Q10))/3,(I10+(P10+O10)+(R10+Q10)+(T10+S10))/4)))),2) -> 1.25 | I10: 1.25 | J10: =IF(N10="","",IF((I10-$I$4)=0,0,((I10-$I$4-(N10-$N$4))/(I10-$I$4)))) -> 0.0026666667 | K10: =(I10-$I$5)-(N10-$N$5) -> 0.0033333333 | L10: R103 Bothas Hill | M10: 60 | N10: =IF(P10="",((I10-I9)+H9),IF(R10="",(P10+O10),IF(T10="",((P10+O10)+(R10+Q10))/2,((P10+O10)+(R10+Q10)+(T10+S10))/3))) -> 1.2466667 | P10: 1.24 | R10: 1.25 | T10: 1.25 | U10: =IF(W10="","",IF(Y10="",W10,IF(AA10<1,ROUND((Y10+W10)/2,5),IF(AC10<1,ROUND((Y10+AA10+W10)/3,5),ROUND((Y10+AA10+AC10+W10)/4,5))))) | V10: =IF(X10="","",IF(Z10<1,ROUND(X10,5),IF(AB10<1,ROUND((X10+Z10)/2,5),IF(AD10<1,ROUND((X10+Z10+AB10)/3,5),ROUND((X10+Z10+AB10+AD10)/4,5))))) | AE10: =IF(A10="","",A10) -> 26 | AF10: =IF(B10="","",B10) | AG10: =IF(C10="","",C10) -> l | AH10: =IF(D10="","",D10) -> 30 | AI10: =H10 -> 1.25 | AJ10: o | AM10: =IF(OR(AJ10="",AJ10="m"),AM9,IF(AH10<>"",AH10,"")) -> 30 | AN10: =IF(AJ10<>"",IF(AJ10="o",VLOOKUP(AM10,OpenSect!$A$1:$D$11,2),IF(AJ10="u",VLOOKUP(AM10,UpHill!$A$1:$D$35,2),IF(AJ10="d",VLOOKUP(AM10,DownHill!$A$3:$D$29,2),IF(AJ10="f",VLOOKUP(AM10,FlatUnd!$A$2:$D$30,2),IF(AJ10="t",VLOOKUP(AM10,TimeAdd!$A$1:$D$176,2),IF(AJ10="l",VLOOKUP(AM10,SLimit!$A$1:$D$8,2),AN9)))))),AN9) -> 30 | AO10: =IF(AJ10<>"",IF(AJ10="o",VLOOKUP(AM10,OpenSect!$A$1:$D$11,3),IF(AJ10="u",VLOOKUP(AM10,UpHill!$A$1:$D$35,3),IF(AJ10="d",VLOOKUP(AM10,DownHill!$A$3:$D$29,3),IF(AJ10="f",VLOOKUP(AM10,FlatUnd!$A$2:$D$30,3),IF(AJ10="t",VLOOKUP(AM10,TimeAdd!$A$1:$D$18,3),IF(AJ10="l",VLOOKUP(AM10,SLimit!$A$1:$D$8,3),AO9)))))),AO9) -> 30 | AP10: =IF(AJ10<>"",IF(AJ10="o",VLOOKUP(AM10,OpenSect!$A$1:$D$11,4),IF(AJ10="u",VLOOKUP(AM10,UpHill!$A$1:$D$35,4),IF(AJ10="d",VLOOKUP(AM10,DownHill!$A$3:$D$29,4),IF(AJ10="f",VLOOKUP(AM10,FlatUnd!$A$2:$D$30,4),IF(AJ10="t",VLOOKUP(AM10,TimeAdd!$A$1:$D$18,4),IF(AJ10="l",VLOOKUP(AM10,SLimit!$A$1:$D$8,4),AP9)))))),AP9) -> 30 | AQ10: =M10 -> 60 | AR10: =L10 -> R103 Bothas Hill | AU10: =IF(GroupStTimes!$A$8=0,MIN(CB10,CD10,CF10),MIN(BZ10,CB10,CD10,CF10)) -> 0.25243056 | AV10: =IF(GroupStTimes!$A$8=0,MAX(CC10,CE10,CG10),MAX(CA10,CC10,CE10,CG10)) -> 0.315625 | AW10: =IF(U10="","",CONCATENATE(FIXED(U10,5)," ",FIXED(V10,5))) | AX10: =IF(AJ10="m",ROUND(W10,5),"") | AY10: =IF(AJ10="m",ROUND(X10,5),"") | AZ10: =IF(AND(AM9=AM8,AN9=AN8,AO9=AO8,AP9=AP8,AJ10<>"t"),AZ9,IF(AJ10="t",AI10,AI9)) -> 0 | BA10: =IF(AND($AM9=$AM8,$AN9=AN8,$AO9=$AO8,$AP9=$AP8,$AJ10<>"t"),BA9,BZ9) -> 0.25069444 | BB10: =IF(AND($AM9=$AM8,$AN9=AN8,$AO9=$AO8,$AP9=$AP8,$AJ10<>"t"),BB9,CA9) -> 0.25625 | BC10: =IF(AND($AM9=$AM8,$AN9=AN8,$AO9=$AO8,$AP9=$AP8,$AJ10<>"t"),BC9,CB9) -> 0.25694444 | BD10: =IF(AND($AM9=$AM8,$AN9=AN8,$AO9=$AO8,$AP9=$AP8,$AJ10<>"t"),BD9,CC9) -> 0.30277778 | BE10: =IF(AND($AM9=$AM8,$AN9=AN8,$AO9=$AO8,$AP9=$AP8,$AJ10<>"t"),BE9,CD9) -> 0.30347222 | BF10: =IF(AND($AM9=$AM8,$AN9=AN8,$AO9=$AO8,$AP9=$AP8,$AJ10<>"t"),BF9,CE9) -> 0.31388889 | BG10: =IF(AND($AM9=$AM8,$AN9=AN8,$AO9=$AO8,$AP9=$AP8,$AJ10<>"t"),BG9,CF9) -> 0.31458333 | BH10: =IF(AND($AM9=$AM8,$AN9=AN8,$AO9=$AO8,$AP9=$AP8,$AJ10<>"t"),BH9,CG9) -> 0.31388889 | BI10: =AI10-AZ10 -> 1.25 | BJ10: =IF($AJ9="t",IF(AM8=0,0,$BI10/AM8),IF(AM9=0,0,$BI10/AM9)) -> 0.041666667 | BK10: =IF($AJ9="t",IF(AN8=0,0,$BI10/AN8),IF(AN9=0,0,$BI10/AN9)) -> 0.041666667 | BL10: =IF($AJ9="t",IF(AO8=0,0,$BI10/AO8),IF(AO9=0,0,$BI10/AO9)) -> 0.041666667 | BM10: =IF($AJ9="t",IF(AP8=0,0,$BI10/AP8),IF(AP9=0,0,$BI10/AP9)) -> 0.041666667 | BN10: =IF(AJ10="t",0,INT(BJ10)) -> 0 | BO10: =IF(AJ10="t",AM10,IF(INT((BJ10-BN10)*60)<0,1,INT((BJ10-BN10)*60))) -> 2 | BP10: =IF(AJ10="t",0,ROUND((((BJ10-BN10)*60)-BO10)*60,0)) -> 30 | BQ10: =IF(AJ10="t",0,INT(BK10)) -> 0 | BR10: =IF(AJ10="t",AN10,IF(INT((BK10-BQ10)*60)<0,1,INT((BK10-BQ10)*60))) -> 2 | BS10: =IF(AJ10="t",0,ROUND((((BK10-BQ10)*60)-BR10)*60,0)) -> 30 | BT10: =IF(AJ10="t",0,INT(BL10)) -> 0 | BU10: =IF(AJ10="t",AO10,IF(INT((BL10-BT10)*60)<0,1,INT((BL10-BT10)*60))) -> 2 | BV10: =IF(AJ10="t",0,ROUND((((BL10-BT10)*60)-BU10)*60,0)) -> 30 | BW10: =IF(AJ10="t",0,INT(BM10)) -> 0 | BX10: =IF(AJ10="t",AP10,IF(INT((BM10-BW10)*60)<0,1,INT((BM10-BW10)*60))) -> 2 | BY10: =IF(AJ10="t",0,ROUND((((BM10-BW10)*60)-BX10)*60,0)) -> 30 | BZ10: =BA10+TIME(BN10,BO10,BP10) -> 0.25243056 | CA10: =BB10+TIME(BN10,BO10,BP10) -> 0.25798611 | CB10: =BC10+TIME(BQ10,BR10,BS10) -> 0.25868056 | CC10: =BD10+TIME(BQ10,BR10,BS10) -> 0.30451389 | CD10: =BE10+TIME(BT10,BU10,BV10) -> 0.30520833 | CE10: =BF10+TIME(BT10,BU10,BV10) -> 0.315625 | CF10: =BG10+TIME(BW10,BX10,BY10) -> 0.31631944 | CG10: =BH10+TIME(BW10,BX10,BY10) -> 0.315625 | CL10: 60
A11: 26 | C11: o | D11: 30 | G11: 1.4 | H11: =ROUND(IF(G11="",N11,IF(P11="",I11,IF(R11="",(I11+(P11+O11))/2,IF(T11="",(I11+(P11+O11)+(R11+Q11))/3,(I11+(P11+O11)+(R11+Q11)+(T11+S11))/4)))),2) -> 1.4 | I11: 1.4 | J11: =IF(N11="","",IF((I11-$I$4)=0,0,((I11-$I$4-(N11-$N$4))/(I11-$I$4)))) -> -0.0023809524 | K11: =(I11-$I$5)-(N11-$N$5) -> -0.0033333333 | L11: Traffic Light Carry Straight On.{ 0km Stone} Stay on Old Main road. Be careful of bad road surface. | M11: 60 | N11: =IF(P11="",((I11-I10)+H10),IF(R11="",(P11+O11),IF(T11="",((P11+O11)+(R11+Q11))/2,((P11+O11)+(R11+Q11)+(T11+S11))/3))) -> 1.4033333 | P11: 1.4 | R11: 1.4 | T11: 1.41 | U11: =IF(W11="","",IF(Y11="",W11,IF(AA11<1,ROUND((Y11+W11)/2,5),IF(AC11<1,ROUND((Y11+AA11+W11)/3,5),ROUND((Y11+AA11+AC11+W11)/4,5))))) | V11: =IF(X11="","",IF(Z11<1,ROUND(X11,5),IF(AB11<1,ROUND((X11+Z11)/2,5),IF(AD11<1,ROUND((X11+Z11+AB11)/3,5),ROUND((X11+Z11+AB11+AD11)/4,5))))) | AE11: =IF(A11="","",A11) -> 26 | AF11: =IF(B11="","",B11) | AG11: =IF(C11="","",C11) -> o | AH11: =IF(D11="","",D11) -> 30 | AI11: =H11 -> 1.4 | AJ11: o | AM11: =IF(OR(AJ11="",AJ11="m"),AM10,IF(AH11<>"",AH11,"")) -> 30 | AN11: =IF(AJ11<>"",IF(AJ11="o",VLOOKUP(AM11,OpenSect!$A$1:$D$11,2),IF(AJ11="u",VLOOKUP(AM11,UpHill!$A$1:$D$35,2),IF(AJ11="d",VLOOKUP(AM11,DownHill!$A$3:$D$29,2),IF(AJ11="f",VLOOKUP(AM11,FlatUnd!$A$2:$D$30,2),IF(AJ11="t",VLOOKUP(AM11,TimeAdd!$A$1:$D$176,2),IF(AJ11="l",VLOOKUP(AM11,SLimit!$A$1:$D$8,2),AN10)))))),AN10) -> 30 | AO11: =IF(AJ11<>"",IF(AJ11="o",VLOOKUP(AM11,OpenSect!$A$1:$D$11,3),IF(AJ11="u",VLOOKUP(AM11,UpHill!$A$1:$D$35,3),IF(AJ11="d",VLOOKUP(AM11,DownHill!$A$3:$D$29,3),IF(AJ11="f",VLOOKUP(AM11,FlatUnd!$A$2:$D$30,3),IF(AJ11="t",VLOOKUP(AM11,TimeAdd!$A$1:$D$18,3),IF(AJ11="l",VLOOKUP(AM11,SLimit!$A$1:$D$8,3),AO10)))))),AO10) -> 30 | AP11: =IF(AJ11<>"",IF(AJ11="o",VLOOKUP(AM11,OpenSect!$A$1:$D$11,4),IF(AJ11="u",VLOOKUP(AM11,UpHill!$A$1:$D$35,4),IF(AJ11="d",VLOOKUP(AM11,DownHill!$A$3:$D$29,4),IF(AJ11="f",VLOOKUP(AM11,FlatUnd!$A$2:$D$30,4),IF(AJ11="t",VLOOKUP(AM11,TimeAdd!$A$1:$D$18,4),IF(AJ11="l",VLOOKUP(AM11,SLimit!$A$1:$D$8,4),AP10)))))),AP10) -> 30 | AQ11: =M11 -> 60 | AR11: =L11 -> Traffic Light Carry Straight On.{ 0km Stone} Stay on Old Main road. Be careful of bad road surface. | AU11: =IF(GroupStTimes!$A$8=0,MIN(CB11,CD11,CF11),MIN(BZ11,CB11,CD11,CF11)) -> 0.25263889 | AV11: =IF(GroupStTimes!$A$8=0,MAX(CC11,CE11,CG11),MAX(CA11,CC11,CE11,CG11)) -> 0.31583333 | AW11: =IF(U11="","",CONCATENATE(FIXED(U11,5)," ",FIXED(V11,5))) | AX11: =IF(AJ11="m",ROUND(W11,5),"") | AY11: =IF(AJ11="m",ROUND(X11,5),"") | AZ11: =IF(AND(AM10=AM9,AN10=AN9,AO10=AO9,AP10=AP9,AJ11<>"t"),AZ10,IF(AJ11="t",AI11,AI10)) -> 0 | BA11: =IF(AND($AM10=$AM9,$AN10=AN9,$AO10=$AO9,$AP10=$AP9,$AJ11<>"t"),BA10,BZ10) -> 0.25069444 | BB11: =IF(AND($AM10=$AM9,$AN10=AN9,$AO10=$AO9,$AP10=$AP9,$AJ11<>"t"),BB10,CA10) -> 0.25625 | BC11: =IF(AND($AM10=$AM9,$AN10=AN9,$AO10=$AO9,$AP10=$AP9,$AJ11<>"t"),BC10,CB10) -> 0.25694444 | BD11: =IF(AND($AM10=$AM9,$AN10=AN9,$AO10=$AO9,$AP10=$AP9,$AJ11<>"t"),BD10,CC10) -> 0.30277778 | BE11: =IF(AND($AM10=$AM9,$AN10=AN9,$AO10=$AO9,$AP10=$AP9,$AJ11<>"t"),BE10,CD10) -> 0.30347222 | BF11: =IF(AND($AM10=$AM9,$AN10=AN9,$AO10=$AO9,$AP10=$AP9,$AJ11<>"t"),BF10,CE10) -> 0.31388889 | BG11: =IF(AND($AM10=$AM9,$AN10=AN9,$AO10=$AO9,$AP10=$AP9,$AJ11<>"t"),BG10,CF10) -> 0.31458333 | BH11: =IF(AND($AM10=$AM9,$AN10=AN9,$AO10=$AO9,$AP10=$AP9,$AJ11<>"t"),BH10,CG10) -> 0.31388889 | BI11: =AI11-AZ11 -> 1.4 | BJ11: =IF($AJ10="t",IF(AM9=0,0,$BI11/AM9),IF(AM10=0,0,$BI11/AM10)) -> 0.046666667 | BK11: =IF($AJ10="t",IF(AN9=0,0,$BI11/AN9),IF(AN10=0,0,$BI11/AN10)) -> 0.046666667 | BL11: =IF($AJ10="t",IF(AO9=0,0,$BI11/AO9),IF(AO10=0,0,$BI11/AO10)) -> 0.046666667 | BM11: =IF($AJ10="t",IF(AP9=0,0,$BI11/AP9),IF(AP10=0,0,$BI11/AP10)) -> 0.046666667 | BN11: =IF(AJ11="t",0,INT(BJ11)) -> 0 | BO11: =IF(AJ11="t",AM11,IF(INT((BJ11-BN11)*60)<0,1,INT((BJ11-BN11)*60))) -> 2 | BP11: =IF(AJ11="t",0,ROUND((((BJ11-BN11)*60)-BO11)*60,0)) -> 48 | BQ11: =IF(AJ11="t",0,INT(BK11)) -> 0 | BR11: =IF(AJ11="t",AN11,IF(INT((BK11-BQ11)*60)<0,1,INT((BK11-BQ11)*60))) -> 2 | BS11: =IF(AJ11="t",0,ROUND((((BK11-BQ11)*60)-BR11)*60,0)) -> 48 | BT11: =IF(AJ11="t",0,INT(BL11)) -> 0 | BU11: =IF(AJ11="t",AO11,IF(INT((BL11-BT11)*60)<0,1,INT((BL11-BT11)*60))) -> 2 | BV11: =IF(AJ11="t",0,ROUND((((BL11-BT11)*60)-BU11)*60,0)) -> 48 | BW11: =IF(AJ11="t",0,INT(BM11)) -> 0 | BX11: =IF(AJ11="t",AP11,IF(INT((BM11-BW11)*60)<0,1,INT((BM11-BW11)*60))) -> 2 | BY11: =IF(AJ11="t",0,ROUND((((BM11-BW11)*60)-BX11)*60,0)) -> 48 | BZ11: =BA11+TIME(BN11,BO11,BP11) -> 0.25263889 | CA11: =BB11+TIME(BN11,BO11,BP11) -> 0.25819444 | CB11: =BC11+TIME(BQ11,BR11,BS11) -> 0.25888889 | CC11: =BD11+TIME(BQ11,BR11,BS11) -> 0.30472222 | CD11: =BE11+TIME(BT11,BU11,BV11) -> 0.30541667 | CE11: =BF11+TIME(BT11,BU11,BV11) -> 0.31583333 | CF11: =BG11+TIME(BW11,BX11,BY11) -> 0.31652778 | CG11: =BH11+TIME(BW11,BX11,BY11) -> 0.31583333 | CL11: 60
A12: 26 | G12: 1.62 | H12: =ROUND(IF(G12="",N12,IF(P12="",I12,IF(R12="",(I12+(P12+O12))/2,IF(T12="",(I12+(P12+O12)+(R12+Q12))/3,(I12+(P12+O12)+(R12+Q12)+(T12+S12))/4)))),2) -> 1.62 | I12: 1.62 | J12: =IF(N12="","",IF((I12-$I$4)=0,0,((I12-$I$4-(N12-$N$4))/(I12-$I$4)))) -> -0.0020576132 | K12: =(I12-$I$5)-(N12-$N$5) -> -0.0033333333 | L12: 60 Speed limit | M12: 60 | N12: =IF(P12="",((I12-I11)+H11),IF(R12="",(P12+O12),IF(T12="",((P12+O12)+(R12+Q12))/2,((P12+O12)+(R12+Q12)+(T12+S12))/3))) -> 1.6233333 | P12: 1.62 | R12: 1.62 | T12: 1.63 | U12: =IF(W12="","",IF(Y12="",W12,IF(AA12<1,ROUND((Y12+W12)/2,5),IF(AC12<1,ROUND((Y12+AA12+W12)/3,5),ROUND((Y12+AA12+AC12+W12)/4,5))))) | V12: =IF(X12="","",IF(Z12<1,ROUND(X12,5),IF(AB12<1,ROUND((X12+Z12)/2,5),IF(AD12<1,ROUND((X12+Z12+AB12)/3,5),ROUND((X12+Z12+AB12+AD12)/4,5))))) | AE12: =IF(A12="","",A12) -> 26 | AF12: =IF(B12="","",B12) | AG12: =IF(C12="","",C12) | AH12: =IF(D12="","",D12) | AI12: =H12 -> 1.62 | AM12: =IF(OR(AJ12="",AJ12="m"),AM11,IF(AH12<>"",AH12,"")) -> 30 | AN12: =IF(AJ12<>"",IF(AJ12="o",VLOOKUP(AM12,OpenSect!$A$1:$D$11,2),IF(AJ12="u",VLOOKUP(AM12,UpHill!$A$1:$D$35,2),IF(AJ12="d",VLOOKUP(AM12,DownHill!$A$3:$D$29,2),IF(AJ12="f",VLOOKUP(AM12,FlatUnd!$A$2:$D$30,2),IF(AJ12="t",VLOOKUP(AM12,TimeAdd!$A$1:$D$176,2),IF(AJ12="l",VLOOKUP(AM12,SLimit!$A$1:$D$8,2),AN11)))))),AN11) -> 30 | AO12: =IF(AJ12<>"",IF(AJ12="o",VLOOKUP(AM12,OpenSect!$A$1:$D$11,3),IF(AJ12="u",VLOOKUP(AM12,UpHill!$A$1:$D$35,3),IF(AJ12="d",VLOOKUP(AM12,DownHill!$A$3:$D$29,3),IF(AJ12="f",VLOOKUP(AM12,FlatUnd!$A$2:$D$30,3),IF(AJ12="t",VLOOKUP(AM12,TimeAdd!$A$1:$D$18,3),IF(AJ12="l",VLOOKUP(AM12,SLimit!$A$1:$D$8,3),AO11)))))),AO11) -> 30 | AP12: =IF(AJ12<>"",IF(AJ12="o",VLOOKUP(AM12,OpenSect!$A$1:$D$11,4),IF(AJ12="u",VLOOKUP(AM12,UpHill!$A$1:$D$35,4),IF(AJ12="d",VLOOKUP(AM12,DownHill!$A$3:$D$29,4),IF(AJ12="f",VLOOKUP(AM12,FlatUnd!$A$2:$D$30,4),IF(AJ12="t",VLOOKUP(AM12,TimeAdd!$A$1:$D$18,4),IF(AJ12="l",VLOOKUP(AM12,SLimit!$A$1:$D$8,4),AP11)))))),AP11) -> 30 | AQ12: =M12 -> 60 | AR12: =L12 -> 60 Speed limit | AU12: =IF(GroupStTimes!$A$8=0,MIN(CB12,CD12,CF12),MIN(BZ12,CB12,CD12,CF12)) -> 0.25293981 | AV12: =IF(GroupStTimes!$A$8=0,MAX(CC12,CE12,CG12),MAX(CA12,CC12,CE12,CG12)) -> 0.31613426 | AW12: =IF(U12="","",CONCATENATE(FIXED(U12,5)," ",FIXED(V12,5))) | AX12: =IF(AJ12="m",ROUND(W12,5),"") | AY12: =IF(AJ12="m",ROUND(X12,5),"") | AZ12: =IF(AND(AM11=AM10,AN11=AN10,AO11=AO10,AP11=AP10,AJ12<>"t"),AZ11,IF(AJ12="t",AI12,AI11)) -> 0 | BA12: =IF(AND($AM11=$AM10,$AN11=AN10,$AO11=$AO10,$AP11=$AP10,$AJ12<>"t"),BA11,BZ11) -> 0.25069444 | BB12: =IF(AND($AM11=$AM10,$AN11=AN10,$AO11=$AO10,$AP11=$AP10,$AJ12<>"t"),BB11,CA11) -> 0.25625 | BC12: =IF(AND($AM11=$AM10,$AN11=AN10,$AO11=$AO10,$AP11=$AP10,$AJ12<>"t"),BC11,CB11) -> 0.25694444 | BD12: =IF(AND($AM11=$AM10,$AN11=AN10,$AO11=$AO10,$AP11=$AP10,$AJ12<>"t"),BD11,CC11) -> 0.30277778 | BE12: =IF(AND($AM11=$AM10,$AN11=AN10,$AO11=$AO10,$AP11=$AP10,$AJ12<>"t"),BE11,CD11) -> 0.30347222 | BF12: =IF(AND($AM11=$AM10,$AN11=AN10,$AO11=$AO10,$AP11=$AP10,$AJ12<>"t"),BF11,CE11) -> 0.31388889 | BG12: =IF(AND($AM11=$AM10,$AN11=AN10,$AO11=$AO10,$AP11=$AP10,$AJ12<>"t"),BG11,CF11) -> 0.31458333 | BH12: =IF(AND($AM11=$AM10,$AN11=AN10,$AO11=$AO10,$AP11=$AP10,$AJ12<>"t"),BH11,CG11) -> 0.31388889 | BI12: =AI12-AZ12 -> 1.62 | BJ12: =IF($AJ11="t",IF(AM10=0,0,$BI12/AM10),IF(AM11=0,0,$BI12/AM11)) -> 0.054 | BK12: =IF($AJ11="t",IF(AN10=0,0,$BI12/AN10),IF(AN11=0,0,$BI12/AN11)) -> 0.054 | BL12: =IF($AJ11="t",IF(AO10=0,0,$BI12/AO10),IF(AO11=0,0,$BI12/AO11)) -> 0.054 | BM12: =IF($AJ11="t",IF(AP10=0,0,$BI12/AP10),IF(AP11=0,0,$BI12/AP11)) -> 0.054 | BN12: =IF(AJ12="t",0,INT(BJ12)) -> 0 | BO12: =IF(AJ12="t",AM12,IF(INT((BJ12-BN12)*60)<0,1,INT((BJ12-BN12)*60))) -> 3 | BP12: =IF(AJ12="t",0,ROUND((((BJ12-BN12)*60)-BO12)*60,0)) -> 14 | BQ12: =IF(AJ12="t",0,INT(BK12)) -> 0 | BR12: =IF(AJ12="t",AN12,IF(INT((BK12-BQ12)*60)<0,1,INT((BK12-BQ12)*60))) -> 3 | BS12: =IF(AJ12="t",0,ROUND((((BK12-BQ12)*60)-BR12)*60,0)) -> 14 | BT12: =IF(AJ12="t",0,INT(BL12)) -> 0 | BU12: =IF(AJ12="t",AO12,IF(INT((BL12-BT12)*60)<0,1,INT((BL12-BT12)*60))) -> 3 | BV12: =IF(AJ12="t",0,ROUND((((BL12-BT12)*60)-BU12)*60,0)) -> 14 | BW12: =IF(AJ12="t",0,INT(BM12)) -> 0 | BX12: =IF(AJ12="t",AP12,IF(INT((BM12-BW12)*60)<0,1,INT((BM12-BW12)*60))) -> 3 | BY12: =IF(AJ12="t",0,ROUND((((BM12-BW12)*60)-BX12)*60,0)) -> 14 | BZ12: =BA12+TIME(BN12,BO12,BP12) -> 0.25293981 | CA12: =BB12+TIME(BN12,BO12,BP12) -> 0.25849537 | CB12: =BC12+TIME(BQ12,BR12,BS12) -> 0.25918981 | CC12: =BD12+TIME(BQ12,BR12,BS12) -> 0.30502315 | CD12: =BE12+TIME(BT12,BU12,BV12) -> 0.30571759 | CE12: =BF12+TIME(BT12,BU12,BV12) -> 0.31613426 | CF12: =BG12+TIME(BW12,BX12,BY12) -> 0.3168287 | CG12: =BH12+TIME(BW12,BX12,BY12) -> 0.31613426 | CL12: 60
A13: 26 | G13: 1.65 | H13: =ROUND(IF(G13="",N13,IF(P13="",I13,IF(R13="",(I13+(P13+O13))/2,IF(T13="",(I13+(P13+O13)+(R13+Q13))/3,(I13+(P13+O13)+(R13+Q13)+(T13+S13))/4)))),2) -> 1.65 | I13: 1.65 | J13: =IF(N13="","",IF((I13-$I$4)=0,0,((I13-$I$4-(N13-$N$4))/(I13-$I$4)))) -> -0.002020202 | K13: =(I13-$I$5)-(N13-$N$5) -> -0.0033333333 | L13: R103 Bothas Hill 4 | M13: 60 | N13: =IF(P13="",((I13-I12)+H12),IF(R13="",(P13+O13),IF(T13="",((P13+O13)+(R13+Q13))/2,((P13+O13)+(R13+Q13)+(T13+S13))/3))) -> 1.6533333 | P13: 1.65 | R13: 1.65 | T13: 1.66 | U13: =IF(W13="","",IF(Y13="",W13,IF(AA13<1,ROUND((Y13+W13)/2,5),IF(AC13<1,ROUND((Y13+AA13+W13)/3,5),ROUND((Y13+AA13+AC13+W13)/4,5))))) | V13: =IF(X13="","",IF(Z13<1,ROUND(X13,5),IF(AB13<1,ROUND((X13+Z13)/2,5),IF(AD13<1,ROUND((X13+Z13+AB13)/3,5),ROUND((X13+Z13+AB13+AD13)/4,5))))) | AE13: =IF(A13="","",A13) -> 26 | AF13: =IF(B13="","",B13) | AG13: =IF(C13="","",C13) | AH13: =IF(D13="","",D13) | AI13: =H13 -> 1.65 | AM13: =IF(OR(AJ13="",AJ13="m"),AM12,IF(AH13<>"",AH13,"")) -> 30 | AN13: =IF(AJ13<>"",IF(AJ13="o",VLOOKUP(AM13,OpenSect!$A$1:$D$11,2),IF(AJ13="u",VLOOKUP(AM13,UpHill!$A$1:$D$35,2),IF(AJ13="d",VLOOKUP(AM13,DownHill!$A$3:$D$29,2),IF(AJ13="f",VLOOKUP(AM13,FlatUnd!$A$2:$D$30,2),IF(AJ13="t",VLOOKUP(AM13,TimeAdd!$A$1:$D$176,2),IF(AJ13="l",VLOOKUP(AM13,SLimit!$A$1:$D$8,2),AN12)))))),AN12) -> 30 | AO13: =IF(AJ13<>"",IF(AJ13="o",VLOOKUP(AM13,OpenSect!$A$1:$D$11,3),IF(AJ13="u",VLOOKUP(AM13,UpHill!$A$1:$D$35,3),IF(AJ13="d",VLOOKUP(AM13,DownHill!$A$3:$D$29,3),IF(AJ13="f",VLOOKUP(AM13,FlatUnd!$A$2:$D$30,3),IF(AJ13="t",VLOOKUP(AM13,TimeAdd!$A$1:$D$18,3),IF(AJ13="l",VLOOKUP(AM13,SLimit!$A$1:$D$8,3),AO12)))))),AO12) -> 30 | AP13: =IF(AJ13<>"",IF(AJ13="o",VLOOKUP(AM13,OpenSect!$A$1:$D$11,4),IF(AJ13="u",VLOOKUP(AM13,UpHill!$A$1:$D$35,4),IF(AJ13="d",VLOOKUP(AM13,DownHill!$A$3:$D$29,4),IF(AJ13="f",VLOOKUP(AM13,FlatUnd!$A$2:$D$30,4),IF(AJ13="t",VLOOKUP(AM13,TimeAdd!$A$1:$D$18,4),IF(AJ13="l",VLOOKUP(AM13,SLimit!$A$1:$D$8,4),AP12)))))),AP12) -> 30 | AQ13: =M13 -> 60 | AR13: =L13 -> R103 Bothas Hill 4 | AU13: =IF(GroupStTimes!$A$8=0,MIN(CB13,CD13,CF13),MIN(BZ13,CB13,CD13,CF13)) -> 0.25298611 | AV13: =IF(GroupStTimes!$A$8=0,MAX(CC13,CE13,CG13),MAX(CA13,CC13,CE13,CG13)) -> 0.31618056 | AW13: =IF(U13="","",CONCATENATE(FIXED(U13,5)," ",FIXED(V13,5))) | AX13: =IF(AJ13="m",ROUND(W13,5),"") | AY13: =IF(AJ13="m",ROUND(X13,5),"") | AZ13: =IF(AND(AM12=AM11,AN12=AN11,AO12=AO11,AP12=AP11,AJ13<>"t"),AZ12,IF(AJ13="t",AI13,AI12)) -> 0 | BA13: =IF(AND($AM12=$AM11,$AN12=AN11,$AO12=$AO11,$AP12=$AP11,$AJ13<>"t"),BA12,BZ12) -> 0.25069444 | BB13: =IF(AND($AM12=$AM11,$AN12=AN11,$AO12=$AO11,$AP12=$AP11,$AJ13<>"t"),BB12,CA12) -> 0.25625 | BC13: =IF(AND($AM12=$AM11,$AN12=AN11,$AO12=$AO11,$AP12=$AP11,$AJ13<>"t"),BC12,CB12) -> 0.25694444 | BD13: =IF(AND($AM12=$AM11,$AN12=AN11,$AO12=$AO11,$AP12=$AP11,$AJ13<>"t"),BD12,CC12) -> 0.30277778 | BE13: =IF(AND($AM12=$AM11,$AN12=AN11,$AO12=$AO11,$AP12=$AP11,$AJ13<>"t"),BE12,CD12) -> 0.30347222 | BF13: =IF(AND($AM12=$AM11,$AN12=AN11,$AO12=$AO11,$AP12=$AP11,$AJ13<>"t"),BF12,CE12) -> 0.31388889 | BG13: =IF(AND($AM12=$AM11,$AN12=AN11,$AO12=$AO11,$AP12=$AP11,$AJ13<>"t"),BG12,CF12) -> 0.31458333 | BH13: =IF(AND($AM12=$AM11,$AN12=AN11,$AO12=$AO11,$AP12=$AP11,$AJ13<>"t"),BH12,CG12) -> 0.31388889 | BI13: =AI13-AZ13 -> 1.65 | BJ13: =IF($AJ12="t",IF(AM11=0,0,$BI13/AM11),IF(AM12=0,0,$BI13/AM12)) -> 0.055 | BK13: =IF($AJ12="t",IF(AN11=0,0,$BI13/AN11),IF(AN12=0,0,$BI13/AN12)) -> 0.055 | BL13: =IF($AJ12="t",IF(AO11=0,0,$BI13/AO11),IF(AO12=0,0,$BI13/AO12)) -> 0.055 | BM13: =IF($AJ12="t",IF(AP11=0,0,$BI13/AP11),IF(AP12=0,0,$BI13/AP12)) -> 0.055 | BN13: =IF(AJ13="t",0,INT(BJ13)) -> 0 | BO13: =IF(AJ13="t",AM13,IF(INT((BJ13-BN13)*60)<0,1,INT((BJ13-BN13)*60))) -> 3 | BP13: =IF(AJ13="t",0,ROUND((((BJ13-BN13)*60)-BO13)*60,0)) -> 18 | BQ13: =IF(AJ13="t",0,INT(BK13)) -> 0 | BR13: =IF(AJ13="t",AN13,IF(INT((BK13-BQ13)*60)<0,1,INT((BK13-BQ13)*60))) -> 3 | BS13: =IF(AJ13="t",0,ROUND((((BK13-BQ13)*60)-BR13)*60,0)) -> 18 | BT13: =IF(AJ13="t",0,INT(BL13)) -> 0 | BU13: =IF(AJ13="t",AO13,IF(INT((BL13-BT13)*60)<0,1,INT((BL13-BT13)*60))) -> 3 | BV13: =IF(AJ13="t",0,ROUND((((BL13-BT13)*60)-BU13)*60,0)) -> 18 | BW13: =IF(AJ13="t",0,INT(BM13)) -> 0 | BX13: =IF(AJ13="t",AP13,IF(INT((BM13-BW13)*60)<0,1,INT((BM13-BW13)*60))) -> 3 | BY13: =IF(AJ13="t",0,ROUND((((BM13-BW13)*60)-BX13)*60,0)) -> 18 | BZ13: =BA13+TIME(BN13,BO13,BP13) -> 0.25298611 | CA13: =BB13+TIME(BN13,BO13,BP13) -> 0.25854167 | CB13: =BC13+TIME(BQ13,BR13,BS13) -> 0.25923611 | CC13: =BD13+TIME(BQ13,BR13,BS13) -> 0.30506944 | CD13: =BE13+TIME(BT13,BU13,BV13) -> 0.30576389 | CE13: =BF13+TIME(BT13,BU13,BV13) -> 0.31618056 | CF13: =BG13+TIME(BW13,BX13,BY13) -> 0.316875 | CG13: =BH13+TIME(BW13,BX13,BY13) -> 0.31618056 | CL13: 60
A14: 26 | G14: 1.73 | H14: =ROUND(IF(G14="",N14,IF(P14="",I14,IF(R14="",(I14+(P14+O14))/2,IF(T14="",(I14+(P14+O14)+(R14+Q14))/3,(I14+(P14+O14)+(R14+Q14)+(T14+S14))/4)))),2) -> 1.73 | I14: 1.73 | J14: =IF(N14="","",IF((I14-$I$4)=0,0,((I14-$I$4-(N14-$N$4))/(I14-$I$4)))) -> -0.0019267823 | K14: =(I14-$I$5)-(N14-$N$5) -> -0.0033333333 | L14: Bothas Hill. START of REGULARITY? | M14: 60 | N14: =IF(P14="",((I14-I13)+H13),IF(R14="",(P14+O14),IF(T14="",((P14+O14)+(R14+Q14))/2,((P14+O14)+(R14+Q14)+(T14+S14))/3))) -> 1.7333333 | P14: 1.73 | R14: 1.73 | T14: 1.74 | U14: =IF(W14="","",IF(Y14="",W14,IF(AA14<1,ROUND((Y14+W14)/2,5),IF(AC14<1,ROUND((Y14+AA14+W14)/3,5),ROUND((Y14+AA14+AC14+W14)/4,5))))) | V14: =IF(X14="","",IF(Z14<1,ROUND(X14,5),IF(AB14<1,ROUND((X14+Z14)/2,5),IF(AD14<1,ROUND((X14+Z14+AB14)/3,5),ROUND((X14+Z14+AB14+AD14)/4,5))))) | AE14: =IF(A14="","",A14) -> 26 | AF14: =IF(B14="","",B14) | AG14: =IF(C14="","",C14) | AH14: =IF(D14="","",D14) | AI14: =H14 -> 1.73 | AM14: =IF(OR(AJ14="",AJ14="m"),AM13,IF(AH14<>"",AH14,"")) -> 30 | AN14: =IF(AJ14<>"",IF(AJ14="o",VLOOKUP(AM14,OpenSect!$A$1:$D$11,2),IF(AJ14="u",VLOOKUP(AM14,UpHill!$A$1:$D$35,2),IF(AJ14="d",VLOOKUP(AM14,DownHill!$A$3:$D$29,2),IF(AJ14="f",VLOOKUP(AM14,FlatUnd!$A$2:$D$30,2),IF(AJ14="t",VLOOKUP(AM14,TimeAdd!$A$1:$D$176,2),IF(AJ14="l",VLOOKUP(AM14,SLimit!$A$1:$D$8,2),AN13)))))),AN13) -> 30 | AO14: =IF(AJ14<>"",IF(AJ14="o",VLOOKUP(AM14,OpenSect!$A$1:$D$11,3),IF(AJ14="u",VLOOKUP(AM14,UpHill!$A$1:$D$35,3),IF(AJ14="d",VLOOKUP(AM14,DownHill!$A$3:$D$29,3),IF(AJ14="f",VLOOKUP(AM14,FlatUnd!$A$2:$D$30,3),IF(AJ14="t",VLOOKUP(AM14,TimeAdd!$A$1:$D$18,3),IF(AJ14="l",VLOOKUP(AM14,SLimit!$A$1:$D$8,3),AO13)))))),AO13) -> 30 | AP14: =IF(AJ14<>"",IF(AJ14="o",VLOOKUP(AM14,OpenSect!$A$1:$D$11,4),IF(AJ14="u",VLOOKUP(AM14,UpHill!$A$1:$D$35,4),IF(AJ14="d",VLOOKUP(AM14,DownHill!$A$3:$D$29,4),IF(AJ14="f",VLOOKUP(AM14,FlatUnd!$A$2:$D$30,4),IF(AJ14="t",VLOOKUP(AM14,TimeAdd!$A$1:$D$18,4),IF(AJ14="l",VLOOKUP(AM14,SLimit!$A$1:$D$8,4),AP13)))))),AP13) -> 30 | AQ14: =M14 -> 60 | AR14: =L14 -> Bothas Hill. START of REGULARITY? | AU14: =IF(GroupStTimes!$A$8=0,MIN(CB14,CD14,CF14),MIN(BZ14,CB14,CD14,CF14)) -> 0.25310185 | AV14: =IF(GroupStTimes!$A$8=0,MAX(CC14,CE14,CG14),MAX(CA14,CC14,CE14,CG14)) -> 0.3162963 | AW14: =IF(U14="","",CONCATENATE(FIXED(U14,5)," ",FIXED(V14,5))) | AX14: =IF(AJ14="m",ROUND(W14,5),"") | AY14: =IF(AJ14="m",ROUND(X14,5),"") | AZ14: =IF(AND(AM13=AM12,AN13=AN12,AO13=AO12,AP13=AP12,AJ14<>"t"),AZ13,IF(AJ14="t",AI14,AI13)) -> 0 | BA14: =IF(AND($AM13=$AM12,$AN13=AN12,$AO13=$AO12,$AP13=$AP12,$AJ14<>"t"),BA13,BZ13) -> 0.25069444 | BB14: =IF(AND($AM13=$AM12,$AN13=AN12,$AO13=$AO12,$AP13=$AP12,$AJ14<>"t"),BB13,CA13) -> 0.25625 | BC14: =IF(AND($AM13=$AM12,$AN13=AN12,$AO13=$AO12,$AP13=$AP12,$AJ14<>"t"),BC13,CB13) -> 0.25694444 | BD14: =IF(AND($AM13=$AM12,$AN13=AN12,$AO13=$AO12,$AP13=$AP12,$AJ14<>"t"),BD13,CC13) -> 0.30277778 | BE14: =IF(AND($AM13=$AM12,$AN13=AN12,$AO13=$AO12,$AP13=$AP12,$AJ14<>"t"),BE13,CD13) -> 0.30347222 | BF14: =IF(AND($AM13=$AM12,$AN13=AN12,$AO13=$AO12,$AP13=$AP12,$AJ14<>"t"),BF13,CE13) -> 0.31388889 | BG14: =IF(AND($AM13=$AM12,$AN13=AN12,$AO13=$AO12,$AP13=$AP12,$AJ14<>"t"),BG13,CF13) -> 0.31458333 | BH14: =IF(AND($AM13=$AM12,$AN13=AN12,$AO13=$AO12,$AP13=$AP12,$AJ14<>"t"),BH13,CG13) -> 0.31388889 | BI14: =AI14-AZ14 -> 1.73 | BJ14: =IF($AJ13="t",IF(AM12=0,0,$BI14/AM12),IF(AM13=0,0,$BI14/AM13)) -> 0.057666667 | BK14: =IF($AJ13="t",IF(AN12=0,0,$BI14/AN12),IF(AN13=0,0,$BI14/AN13)) -> 0.057666667 | BL14: =IF($AJ13="t",IF(AO12=0,0,$BI14/AO12),IF(AO13=0,0,$BI14/AO13)) -> 0.057666667 | BM14: =IF($AJ13="t",IF(AP12=0,0,$BI14/AP12),IF(AP13=0,0,$BI14/AP13)) -> 0.057666667 | BN14: =IF(AJ14="t",0,INT(BJ14)) -> 0 | BO14: =IF(AJ14="t",AM14,IF(INT((BJ14-BN14)*60)<0,1,INT((BJ14-BN14)*60))) -> 3 | BP14: =IF(AJ14="t",0,ROUND((((BJ14-BN14)*60)-BO14)*60,0)) -> 28 | BQ14: =IF(AJ14="t",0,INT(BK14)) -> 0 | BR14: =IF(AJ14="t",AN14,IF(INT((BK14-BQ14)*60)<0,1,INT((BK14-BQ14)*60))) -> 3 | BS14: =IF(AJ14="t",0,ROUND((((BK14-BQ14)*60)-BR14)*60,0)) -> 28 | BT14: =IF(AJ14="t",0,INT(BL14)) -> 0 | BU14: =IF(AJ14="t",AO14,IF(INT((BL14-BT14)*60)<0,1,INT((BL14-BT14)*60))) -> 3 | BV14: =IF(AJ14="t",0,ROUND((((BL14-BT14)*60)-BU14)*60,0)) -> 28 | BW14: =IF(AJ14="t",0,INT(BM14)) -> 0 | BX14: =IF(AJ14="t",AP14,IF(INT((BM14-BW14)*60)<0,1,INT((BM14-BW14)*60))) -> 3 | BY14: =IF(AJ14="t",0,ROUND((((BM14-BW14)*60)-BX14)*60,0)) -> 28 | BZ14: =BA14+TIME(BN14,BO14,BP14) -> 0.25310185 | CA14: =BB14+TIME(BN14,BO14,BP14) -> 0.25865741 | CB14: =BC14+TIME(BQ14,BR14,BS14) -> 0.25935185 | CC14: =BD14+TIME(BQ14,BR14,BS14) -> 0.30518519 | CD14: =BE14+TIME(BT14,BU14,BV14) -> 0.30587963 | CE14: =BF14+TIME(BT14,BU14,BV14) -> 0.3162963 | CF14: =BG14+TIME(BW14,BX14,BY14) -> 0.31699074 | CG14: =BH14+TIME(BW14,BX14,BY14) -> 0.3162963 | CL14: 60
A15: 26 | B15: U1 | G15: 2.04 | H15: =ROUND(IF(G15="",N15,IF(P15="",I15,IF(R15="",(I15+(P15+O15))/2,IF(T15="",(I15+(P15+O15)+(R15+Q15))/3,(I15+(P15+O15)+(R15+Q15)+(T15+S15))/4)))),2) -> 2.02 | I15: 2 | J15: =IF(N15="","",IF((I15-$I$4)=0,0,((I15-$I$4-(N15-$N$4))/(I15-$I$4)))) -> -0.015 | K15: =(I15-$I$5)-(N15-$N$5) -> -0.03 | L15: Warning - Winding road | M15: 60 | N15: =IF(P15="",((I15-I14)+H14),IF(R15="",(P15+O15),IF(T15="",((P15+O15)+(R15+Q15))/2,((P15+O15)+(R15+Q15)+(T15+S15))/3))) -> 2.03 | P15: 2 | R15: 2.04 | T15: 2.05 | U15: =IF(W15="","",IF(Y15="",W15,IF(AA15<1,ROUND((Y15+W15)/2,5),IF(AC15<1,ROUND((Y15+AA15+W15)/3,5),ROUND((Y15+AA15+AC15+W15)/4,5))))) | V15: =IF(X15="","",IF(Z15<1,ROUND(X15,5),IF(AB15<1,ROUND((X15+Z15)/2,5),IF(AD15<1,ROUND((X15+Z15+AB15)/3,5),ROUND((X15+Z15+AB15+AD15)/4,5))))) | AE15: =IF(A15="","",A15) -> 26 | AF15: =IF(B15="","",B15) -> U1 | AG15: =IF(C15="","",C15) | AH15: =IF(D15="","",D15) | AI15: =H15 -> 2.02 | AM15: =IF(OR(AJ15="",AJ15="m"),AM14,IF(AH15<>"",AH15,"")) -> 30 | AN15: =IF(AJ15<>"",IF(AJ15="o",VLOOKUP(AM15,OpenSect!$A$1:$D$11,2),IF(AJ15="u",VLOOKUP(AM15,UpHill!$A$1:$D$35,2),IF(AJ15="d",VLOOKUP(AM15,DownHill!$A$3:$D$29,2),IF(AJ15="f",VLOOKUP(AM15,FlatUnd!$A$2:$D$30,2),IF(AJ15="t",VLOOKUP(AM15,TimeAdd!$A$1:$D$176,2),IF(AJ15="l",VLOOKUP(AM15,SLimit!$A$1:$D$8,2),AN14)))))),AN14) -> 30 | AO15: =IF(AJ15<>"",IF(AJ15="o",VLOOKUP(AM15,OpenSect!$A$1:$D$11,3),IF(AJ15="u",VLOOKUP(AM15,UpHill!$A$1:$D$35,3),IF(AJ15="d",VLOOKUP(AM15,DownHill!$A$3:$D$29,3),IF(AJ15="f",VLOOKUP(AM15,FlatUnd!$A$2:$D$30,3),IF(AJ15="t",VLOOKUP(AM15,TimeAdd!$A$1:$D$18,3),IF(AJ15="l",VLOOKUP(AM15,SLimit!$A$1:$D$8,3),AO14)))))),AO14) -> 30 | AP15: =IF(AJ15<>"",IF(AJ15="o",VLOOKUP(AM15,OpenSect!$A$1:$D$11,4),IF(AJ15="u",VLOOKUP(AM15,UpHill!$A$1:$D$35,4),IF(AJ15="d",VLOOKUP(AM15,DownHill!$A$3:$D$29,4),IF(AJ15="f",VLOOKUP(AM15,FlatUnd!$A$2:$D$30,4),IF(AJ15="t",VLOOKUP(AM15,TimeAdd!$A$1:$D$18,4),IF(AJ15="l",VLOOKUP(AM15,SLimit!$A$1:$D$8,4),AP14)))))),AP14) -> 30 | AQ15: =M15 -> 60 | AR15: =L15 -> Warning - Winding road | AU15: =IF(GroupStTimes!$A$8=0,MIN(CB15,CD15,CF15),MIN(BZ15,CB15,CD15,CF15)) -> 0.25349537 | AV15: =IF(GroupStTimes!$A$8=0,MAX(CC15,CE15,CG15),MAX(CA15,CC15,CE15,CG15)) -> 0.31668981 | AW15: =IF(U15="","",CONCATENATE(FIXED(U15,5)," ",FIXED(V15,5))) | AX15: =IF(AJ15="m",ROUND(W15,5),"") | AY15: =IF(AJ15="m",ROUND(X15,5),"") | AZ15: =IF(AND(AM14=AM13,AN14=AN13,AO14=AO13,AP14=AP13,AJ15<>"t"),AZ14,IF(AJ15="t",AI15,AI14)) -> 0 | BA15: =IF(AND($AM14=$AM13,$AN14=AN13,$AO14=$AO13,$AP14=$AP13,$AJ15<>"t"),BA14,BZ14) -> 0.25069444 | BB15: =IF(AND($AM14=$AM13,$AN14=AN13,$AO14=$AO13,$AP14=$AP13,$AJ15<>"t"),BB14,CA14) -> 0.25625 | BC15: =IF(AND($AM14=$AM13,$AN14=AN13,$AO14=$AO13,$AP14=$AP13,$AJ15<>"t"),BC14,CB14) -> 0.25694444 | BD15: =IF(AND($AM14=$AM13,$AN14=AN13,$AO14=$AO13,$AP14=$AP13,$AJ15<>"t"),BD14,CC14) -> 0.30277778 | BE15: =IF(AND($AM14=$AM13,$AN14=AN13,$AO14=$AO13,$AP14=$AP13,$AJ15<>"t"),BE14,CD14) -> 0.30347222 | BF15: =IF(AND($AM14=$AM13,$AN14=AN13,$AO14=$AO13,$AP14=$AP13,$AJ15<>"t"),BF14,CE14) -> 0.31388889 | BG15: =IF(AND($AM14=$AM13,$AN14=AN13,$AO14=$AO13,$AP14=$AP13,$AJ15<>"t"),BG14,CF14) -> 0.31458333 | BH15: =IF(AND($AM14=$AM13,$AN14=AN13,$AO14=$AO13,$AP14=$AP13,$AJ15<>"t"),BH14,CG14) -> 0.31388889 | BI15: =AI15-AZ15 -> 2.02 | BJ15: =IF($AJ14="t",IF(AM13=0,0,$BI15/AM13),IF(AM14=0,0,$BI15/AM14)) -> 0.067333333 | BK15: =IF($AJ14="t",IF(AN13=0,0,$BI15/AN13),IF(AN14=0,0,$BI15/AN14)) -> 0.067333333 | BL15: =IF($AJ14="t",IF(AO13=0,0,$BI15/AO13),IF(AO14=0,0,$BI15/AO14)) -> 0.067333333 | BM15: =IF($AJ14="t",IF(AP13=0,0,$BI15/AP13),IF(AP14=0,0,$BI15/AP14)) -> 0.067333333 | BN15: =IF(AJ15="t",0,INT(BJ15)) -> 0 | BO15: =IF(AJ15="t",AM15,IF(INT((BJ15-BN15)*60)<0,1,INT((BJ15-BN15)*60))) -> 4 | BP15: =IF(AJ15="t",0,ROUND((((BJ15-BN15)*60)-BO15)*60,0)) -> 2 | BQ15: =IF(AJ15="t",0,INT(BK15)) -> 0 | BR15: =IF(AJ15="t",AN15,IF(INT((BK15-BQ15)*60)<0,1,INT((BK15-BQ15)*60))) -> 4 | BS15: =IF(AJ15="t",0,ROUND((((BK15-BQ15)*60)-BR15)*60,0)) -> 2 | BT15: =IF(AJ15="t",0,INT(BL15)) -> 0 | BU15: =IF(AJ15="t",AO15,IF(INT((BL15-BT15)*60)<0,1,INT((BL15-BT15)*60))) -> 4 | BV15: =IF(AJ15="t",0,ROUND((((BL15-BT15)*60)-BU15)*60,0)) -> 2 | BW15: =IF(AJ15="t",0,INT(BM15)) -> 0 | BX15: =IF(AJ15="t",AP15,IF(INT((BM15-BW15)*60)<0,1,INT((BM15-BW15)*60))) -> 4 | BY15: =IF(AJ15="t",0,ROUND((((BM15-BW15)*60)-BX15)*60,0)) -> 2 | BZ15: =BA15+TIME(BN15,BO15,BP15) -> 0.25349537 | CA15: =BB15+TIME(BN15,BO15,BP15) -> 0.25905093 | CB15: =BC15+TIME(BQ15,BR15,BS15) -> 0.25974537 | CC15: =BD15+TIME(BQ15,BR15,BS15) -> 0.3055787 | CD15: =BE15+TIME(BT15,BU15,BV15) -> 0.30627315 | CE15: =BF15+TIME(BT15,BU15,BV15) -> 0.31668981 | CF15: =BG15+TIME(BW15,BX15,BY15) -> 0.31738426 | CG15: =BH15+TIME(BW15,BX15,BY15) -> 0.31668981 | CL15: 60
